(venv) ➜  memleak git:(master) ✗ valgrind --leak-check=full venv/bin/python main.py
==518217== Memcheck, a memory error detector
==518217== Copyright (C) 2002-2022, and GNU GPL'd, by Julian Seward et al.
==518217== Using Valgrind-3.20.0 and LibVEX; rerun with -h for copyright info
==518217== Command: venv/bin/python main.py
==518217==
==518217== Conditional jump or move depends on uninitialised value(s)
==518217==    at 0x4A7562A: UnknownInlinedFun (longobject.c:71)
==518217==    by 0x4A7562A: _PyLong_FromByteArray (longobject.c:922)
==518217==    by 0x4A75126: UnknownInlinedFun (longobject.c:5946)
==518217==    by 0x4A75126: int_from_bytes (longobject.c.h:389)
==518217==    by 0x4A3FE09: cfunction_vectorcall_FASTCALL_KEYWORDS (methodobject.c:443)
==518217==    by 0x4A3FD76: UnknownInlinedFun (pycore_call.h:92)
==518217==    by 0x4A3FD76: PyObject_Vectorcall (call.c:299)
==518217==    by 0x4A321A3: _PyEval_EvalFrameDefault (ceval.c:4772)
==518217==    by 0x4A2DFC9: UnknownInlinedFun (pycore_ceval.h:73)
==518217==    by 0x4A2DFC9: _PyEval_Vector (ceval.c:6435)
==518217==    by 0x4A46915: UnknownInlinedFun (pycore_call.h:92)
==518217==    by 0x4A46915: object_vacall (call.c:819)
==518217==    by 0x4A6ABA3: PyObject_CallMethodObjArgs (call.c:879)
==518217==    by 0x4A68349: UnknownInlinedFun (import.c:1736)
==518217==    by 0x4A68349: PyImport_ImportModuleLevelObject (import.c:1835)
==518217==    by 0x4A7615F: UnknownInlinedFun (bltinmodule.c:277)
==518217==    by 0x4A7615F: builtin___import__ (bltinmodule.c.h:78)
==518217==    by 0x4A3FE09: cfunction_vectorcall_FASTCALL_KEYWORDS (methodobject.c:443)
==518217==    by 0x4A263A8: UnknownInlinedFun (pycore_call.h:92)
==518217==    by 0x4A263A8: _PyObject_CallFunctionVa (call.c:536)
==518217==
==518217== Use of uninitialised value of size 8
==518217==    at 0x4A75653: UnknownInlinedFun (object.h:502)
==518217==    by 0x4A75653: UnknownInlinedFun (longobject.c:62)
==518217==    by 0x4A75653: UnknownInlinedFun (longobject.c:73)
==518217==    by 0x4A75653: _PyLong_FromByteArray (longobject.c:922)
==518217==    by 0x4A75126: UnknownInlinedFun (longobject.c:5946)
==518217==    by 0x4A75126: int_from_bytes (longobject.c.h:389)
==518217==    by 0x4A3FE09: cfunction_vectorcall_FASTCALL_KEYWORDS (methodobject.c:443)
==518217==    by 0x4A3FD76: UnknownInlinedFun (pycore_call.h:92)
==518217==    by 0x4A3FD76: PyObject_Vectorcall (call.c:299)
==518217==    by 0x4A321A3: _PyEval_EvalFrameDefault (ceval.c:4772)
==518217==    by 0x4A2DFC9: UnknownInlinedFun (pycore_ceval.h:73)
==518217==    by 0x4A2DFC9: _PyEval_Vector (ceval.c:6435)
==518217==    by 0x4A46915: UnknownInlinedFun (pycore_call.h:92)
==518217==    by 0x4A46915: object_vacall (call.c:819)
==518217==    by 0x4A6ABA3: PyObject_CallMethodObjArgs (call.c:879)
==518217==    by 0x4A68349: UnknownInlinedFun (import.c:1736)
==518217==    by 0x4A68349: PyImport_ImportModuleLevelObject (import.c:1835)
==518217==    by 0x4A7615F: UnknownInlinedFun (bltinmodule.c:277)
==518217==    by 0x4A7615F: builtin___import__ (bltinmodule.c.h:78)
==518217==    by 0x4A3FE09: cfunction_vectorcall_FASTCALL_KEYWORDS (methodobject.c:443)
==518217==    by 0x4A263A8: UnknownInlinedFun (pycore_call.h:92)
==518217==    by 0x4A263A8: _PyObject_CallFunctionVa (call.c:536)
==518217==
round=0 mem=133.4M
round=1000 mem=166.8M
round=2000 mem=185.0M
round=3000 mem=196.4M
round=4000 mem=203.0M
round=5000 mem=209.4M
round=6000 mem=217.8M
round=7000 mem=223.0M
round=8000 mem=228.0M
round=9000 mem=233.5M
round=10000 mem=239.2M
==518217==
==518217== HEAP SUMMARY:
==518217==     in use at exit: 17,027,608 bytes in 281,267 blocks
==518217==   total heap usage: 1,808,990 allocs, 1,527,723 frees, 124,977,950 bytes allocated
==518217==
==518217== 48 bytes in 1 blocks are possibly lost in loss record 41 of 328
==518217==    at 0x484386F: malloc (vg_replace_malloc.c:393)
==518217==    by 0x4A15E02: UnknownInlinedFun (obmalloc.c:101)
==518217==    by 0x4A15E02: UnknownInlinedFun (obmalloc.c:586)
==518217==    by 0x4A15E02: UnknownInlinedFun (obmalloc.c:2003)
==518217==    by 0x4A15E02: UnknownInlinedFun (obmalloc.c:1996)
==518217==    by 0x4A15E02: PyObject_Malloc (obmalloc.c:712)
==518217==    by 0x4A1E109: UnknownInlinedFun (gcmodule.c:2283)
==518217==    by 0x4A1E109: _PyObject_GC_NewVar (gcmodule.c:2318)
==518217==    by 0x4A1DECC: _PyTuple_FromArray (tupleobject.c:381)
==518217==    by 0x4A1DC21: UnknownInlinedFun (listobject.c:2582)
==518217==    by 0x4A1DC21: PySequence_Tuple (abstract.c:2059)
==518217==    by 0x4AB3E70: UnknownInlinedFun (typeobject.c:2088)
==518217==    by 0x4AB3E70: mro_internal (typeobject.c:2140)
==518217==    by 0x4A19D14: UnknownInlinedFun (typeobject.c:6215)
==518217==    by 0x4A19D14: UnknownInlinedFun (typeobject.c:6468)
==518217==    by 0x4A19D14: PyType_Ready (typeobject.c:6513)
==518217==    by 0x4AADD91: UnknownInlinedFun (object.c:1986)
==518217==    by 0x4AADD91: UnknownInlinedFun (pylifecycle.c:704)
==518217==    by 0x4AADD91: pycore_interp_init (pylifecycle.c:845)
==518217==    by 0x4AA96E1: UnknownInlinedFun (pylifecycle.c:901)
==518217==    by 0x4AA96E1: pyinit_core.constprop.0 (pylifecycle.c:1064)
==518217==    by 0x4AA9339: Py_InitializeFromConfig (pylifecycle.c:1254)
==518217==    by 0x4AA8F13: pymain_init (main.c:67)
==518217==    by 0x4AA818F: pymain_main (main.c:701)
==518217==
==518217== 48 bytes in 1 blocks are possibly lost in loss record 42 of 328
==518217==    at 0x484386F: malloc (vg_replace_malloc.c:393)
==518217==    by 0x4A15E02: UnknownInlinedFun (obmalloc.c:101)
==518217==    by 0x4A15E02: UnknownInlinedFun (obmalloc.c:586)
==518217==    by 0x4A15E02: UnknownInlinedFun (obmalloc.c:2003)
==518217==    by 0x4A15E02: UnknownInlinedFun (obmalloc.c:1996)
==518217==    by 0x4A15E02: PyObject_Malloc (obmalloc.c:712)
==518217==    by 0x4A1E109: UnknownInlinedFun (gcmodule.c:2283)
==518217==    by 0x4A1E109: _PyObject_GC_NewVar (gcmodule.c:2318)
==518217==    by 0x4A1DECC: _PyTuple_FromArray (tupleobject.c:381)
==518217==    by 0x4A29561: _PyObject_MakeTpCall (call.c:188)
==518217==    by 0x4A2D9C0: UnknownInlinedFun (pycore_call.h:90)
==518217==    by 0x4A2D9C0: UnknownInlinedFun (pycore_call.h:77)
==518217==    by 0x4A2D9C0: PyObject_VectorcallMethod (call.c:855)
==518217==    by 0x4ADFB15: UnknownInlinedFun (abstract.h:116)
==518217==    by 0x4ADFB15: UnknownInlinedFun (_abc.c:720)
==518217==    by 0x4ADFB15: _abc__abc_subclasscheck (_abc.c.h:135)
==518217==    by 0x4A4CA90: cfunction_vectorcall_FASTCALL (methodobject.c:427)
==518217==    by 0x4A3FD76: UnknownInlinedFun (pycore_call.h:92)
==518217==    by 0x4A3FD76: PyObject_Vectorcall (call.c:299)
==518217==    by 0x4A321A3: _PyEval_EvalFrameDefault (ceval.c:4772)
==518217==    by 0x4A2DFC9: UnknownInlinedFun (pycore_ceval.h:73)
==518217==    by 0x4A2DFC9: _PyEval_Vector (ceval.c:6435)
==518217==    by 0x4A6C1EC: UnknownInlinedFun (call.c:393)
==518217==    by 0x4A6C1EC: UnknownInlinedFun (pycore_call.h:92)
==518217==    by 0x4A6C1EC: method_vectorcall (classobject.c:59)
==518217==
==518217== 48 bytes in 1 blocks are possibly lost in loss record 43 of 328
==518217==    at 0x484386F: malloc (vg_replace_malloc.c:393)
==518217==    by 0x4A15E02: UnknownInlinedFun (obmalloc.c:101)
==518217==    by 0x4A15E02: UnknownInlinedFun (obmalloc.c:586)
==518217==    by 0x4A15E02: UnknownInlinedFun (obmalloc.c:2003)
==518217==    by 0x4A15E02: UnknownInlinedFun (obmalloc.c:1996)
==518217==    by 0x4A15E02: PyObject_Malloc (obmalloc.c:712)
==518217==    by 0x4A1E109: UnknownInlinedFun (gcmodule.c:2283)
==518217==    by 0x4A1E109: _PyObject_GC_NewVar (gcmodule.c:2318)
==518217==    by 0x4A1D636: PyTuple_New (tupleobject.c:75)
==518217==    by 0x4A2F0AB: r_object (marshal.c:1215)
==518217==    by 0x4A2F3C9: r_object (marshal.c:1394)
==518217==    by 0x4A2F136: r_object (marshal.c:1221)
==518217==    by 0x4A2F3C9: r_object (marshal.c:1394)
==518217==    by 0x4A2F136: r_object (marshal.c:1221)
==518217==    by 0x4A2F3C9: r_object (marshal.c:1394)
==518217==    by 0x4A2F1EA: r_object (marshal.c:1221)
==518217==    by 0x4A2F3C9: r_object (marshal.c:1394)
==518217==
==518217== 48 bytes in 1 blocks are possibly lost in loss record 44 of 328
==518217==    at 0x484386F: malloc (vg_replace_malloc.c:393)
==518217==    by 0x4A15E02: UnknownInlinedFun (obmalloc.c:101)
==518217==    by 0x4A15E02: UnknownInlinedFun (obmalloc.c:586)
==518217==    by 0x4A15E02: UnknownInlinedFun (obmalloc.c:2003)
==518217==    by 0x4A15E02: UnknownInlinedFun (obmalloc.c:1996)
==518217==    by 0x4A15E02: PyObject_Malloc (obmalloc.c:712)
==518217==    by 0x4A1E109: UnknownInlinedFun (gcmodule.c:2283)
==518217==    by 0x4A1E109: _PyObject_GC_NewVar (gcmodule.c:2318)
==518217==    by 0x4A1DECC: _PyTuple_FromArray (tupleobject.c:381)
==518217==    by 0x4A2DD7D: method_vectorcall_VARARGS (descrobject.c:321)
==518217==    by 0x4A3FD76: UnknownInlinedFun (pycore_call.h:92)
==518217==    by 0x4A3FD76: PyObject_Vectorcall (call.c:299)
==518217==    by 0x4A321A3: _PyEval_EvalFrameDefault (ceval.c:4772)
==518217==    by 0x4A2DFC9: UnknownInlinedFun (pycore_ceval.h:73)
==518217==    by 0x4A2DFC9: _PyEval_Vector (ceval.c:6435)
==518217==    by 0x4A3638A: _PyEval_EvalFrameDefault (ceval.c:5379)
==518217==    by 0x4A2DFC9: UnknownInlinedFun (pycore_ceval.h:73)
==518217==    by 0x4A2DFC9: _PyEval_Vector (ceval.c:6435)
==518217==    by 0x4AB7FAB: PyEval_EvalCode (ceval.c:1154)
==518217==    by 0x4AD0261: UnknownInlinedFun (bltinmodule.c:1075)
==518217==    by 0x4AD0261: builtin_exec (bltinmodule.c.h:465)
==518217==
==518217== 48 bytes in 1 blocks are possibly lost in loss record 45 of 328
==518217==    at 0x484386F: malloc (vg_replace_malloc.c:393)
==518217==    by 0x4A15E02: UnknownInlinedFun (obmalloc.c:101)
==518217==    by 0x4A15E02: UnknownInlinedFun (obmalloc.c:586)
==518217==    by 0x4A15E02: UnknownInlinedFun (obmalloc.c:2003)
==518217==    by 0x4A15E02: UnknownInlinedFun (obmalloc.c:1996)
==518217==    by 0x4A15E02: PyObject_Malloc (obmalloc.c:712)
==518217==    by 0x4A1E109: UnknownInlinedFun (gcmodule.c:2283)
==518217==    by 0x4A1E109: _PyObject_GC_NewVar (gcmodule.c:2318)
==518217==    by 0x4A1D636: PyTuple_New (tupleobject.c:75)
==518217==    by 0x4A6D29F: _PyCode_ConstantKey (codeobject.c:2132)
==518217==    by 0x4A6CFFD: merge_consts_recursive (compile.c:1330)
==518217==    by 0x4ACE47A: compiler_add_const (compile.c:1432)
==518217==    by 0x4AD4352: compiler_call_simple_kw_helper (compile.c:5069)
==518217==    by 0x4ACFEF5: compiler_call_helper (compile.c:5119)
==518217==    by 0x4A6AA68: compiler_visit_expr (compile.c:5946)
==518217==    by 0x4A6880C: UnknownInlinedFun (compile.c:4050)
==518217==    by 0x4A6880C: compiler_visit_stmt (compile.c:4124)
==518217==    by 0x4ACD6A6: compiler_body (compile.c:2167)
==518217==
==518217== 48 bytes in 1 blocks are possibly lost in loss record 46 of 328
==518217==    at 0x484386F: malloc (vg_replace_malloc.c:393)
==518217==    by 0x4A15E02: UnknownInlinedFun (obmalloc.c:101)
==518217==    by 0x4A15E02: UnknownInlinedFun (obmalloc.c:586)
==518217==    by 0x4A15E02: UnknownInlinedFun (obmalloc.c:2003)
==518217==    by 0x4A15E02: UnknownInlinedFun (obmalloc.c:1996)
==518217==    by 0x4A15E02: PyObject_Malloc (obmalloc.c:712)
==518217==    by 0x4A1E109: UnknownInlinedFun (gcmodule.c:2283)
==518217==    by 0x4A1E109: _PyObject_GC_NewVar (gcmodule.c:2318)
==518217==    by 0x4A1D636: PyTuple_New (tupleobject.c:75)
==518217==    by 0x4A6D29F: _PyCode_ConstantKey (codeobject.c:2132)
==518217==    by 0x4A739E1: merge_const_one (compile.c:7883)
==518217==    by 0x4A71E80: UnknownInlinedFun (compile.c:8543)
==518217==    by 0x4A71E80: UnknownInlinedFun (compile.c:8876)
==518217==    by 0x4A71E80: UnknownInlinedFun (compile.c:9258)
==518217==    by 0x4A71E80: assemble (compile.c:8409)
==518217==    by 0x4AC55F4: UnknownInlinedFun (compile.c:2206)
==518217==    by 0x4AC55F4: _PyAST_Compile (compile.c:581)
==518217==    by 0x4AD3649: run_mod (pythonrun.c:1726)
==518217==    by 0x4AE96B1: pyrun_file (pythonrun.c:1630)
==518217==    by 0x4AE8E78: _PyRun_SimpleFileObject (pythonrun.c:440)
==518217==    by 0x4AE8AE7: _PyRun_AnyFileObject (pythonrun.c:79)
==518217==
==518217== 48 bytes in 1 blocks are possibly lost in loss record 47 of 328
==518217==    at 0x484386F: malloc (vg_replace_malloc.c:393)
==518217==    by 0x4A15E02: UnknownInlinedFun (obmalloc.c:101)
==518217==    by 0x4A15E02: UnknownInlinedFun (obmalloc.c:586)
==518217==    by 0x4A15E02: UnknownInlinedFun (obmalloc.c:2003)
==518217==    by 0x4A15E02: UnknownInlinedFun (obmalloc.c:1996)
==518217==    by 0x4A15E02: PyObject_Malloc (obmalloc.c:712)
==518217==    by 0x4A1E109: UnknownInlinedFun (gcmodule.c:2283)
==518217==    by 0x4A1E109: _PyObject_GC_NewVar (gcmodule.c:2318)
==518217==    by 0x4A1D636: PyTuple_New (tupleobject.c:75)
==518217==    by 0x4A6D29F: _PyCode_ConstantKey (codeobject.c:2132)
==518217==    by 0x4A6D354: _PyCode_ConstantKey (codeobject.c:2140)
==518217==    by 0x4A739E1: merge_const_one (compile.c:7883)
==518217==    by 0x4A71450: UnknownInlinedFun (compile.c:7985)
==518217==    by 0x4A71450: assemble (compile.c:8479)
==518217==    by 0x4AC55F4: UnknownInlinedFun (compile.c:2206)
==518217==    by 0x4AC55F4: _PyAST_Compile (compile.c:581)
==518217==    by 0x4AD3649: run_mod (pythonrun.c:1726)
==518217==    by 0x4AE96B1: pyrun_file (pythonrun.c:1630)
==518217==    by 0x4AE8E78: _PyRun_SimpleFileObject (pythonrun.c:440)
==518217==
==518217== 48 bytes in 1 blocks are possibly lost in loss record 48 of 328
==518217==    at 0x484386F: malloc (vg_replace_malloc.c:393)
==518217==    by 0x4A15E02: UnknownInlinedFun (obmalloc.c:101)
==518217==    by 0x4A15E02: UnknownInlinedFun (obmalloc.c:586)
==518217==    by 0x4A15E02: UnknownInlinedFun (obmalloc.c:2003)
==518217==    by 0x4A15E02: UnknownInlinedFun (obmalloc.c:1996)
==518217==    by 0x4A15E02: PyObject_Malloc (obmalloc.c:712)
==518217==    by 0x4A1E109: UnknownInlinedFun (gcmodule.c:2283)
==518217==    by 0x4A1E109: _PyObject_GC_NewVar (gcmodule.c:2318)
==518217==    by 0x4A1DECC: _PyTuple_FromArray (tupleobject.c:381)
==518217==    by 0x4A2DD7D: method_vectorcall_VARARGS (descrobject.c:321)
==518217==    by 0x4A3FD76: UnknownInlinedFun (pycore_call.h:92)
==518217==    by 0x4A3FD76: PyObject_Vectorcall (call.c:299)
==518217==    by 0x4A321A3: _PyEval_EvalFrameDefault (ceval.c:4772)
==518217==    by 0x4A2DFC9: UnknownInlinedFun (pycore_ceval.h:73)
==518217==    by 0x4A2DFC9: _PyEval_Vector (ceval.c:6435)
==518217==    by 0x4A5568C: UnknownInlinedFun (pycore_call.h:92)
==518217==    by 0x4A5568C: PyObject_CallOneArg (call.c:376)
==518217==    by 0x4A4593D: _PyObject_GenericGetAttrWithDict (object.c:1278)
==518217==    by 0x4A2BD98: UnknownInlinedFun (object.c:1368)
==518217==    by 0x4A2BD98: PyObject_GetAttr (object.c:916)
==518217==    by 0x4A32AAA: _PyEval_EvalFrameDefault (ceval.c:3464)
==518217==
==518217== 48 bytes in 1 blocks are possibly lost in loss record 49 of 328
==518217==    at 0x484386F: malloc (vg_replace_malloc.c:393)
==518217==    by 0x4A15E02: UnknownInlinedFun (obmalloc.c:101)
==518217==    by 0x4A15E02: UnknownInlinedFun (obmalloc.c:586)
==518217==    by 0x4A15E02: UnknownInlinedFun (obmalloc.c:2003)
==518217==    by 0x4A15E02: UnknownInlinedFun (obmalloc.c:1996)
==518217==    by 0x4A15E02: PyObject_Malloc (obmalloc.c:712)
==518217==    by 0x4A1E109: UnknownInlinedFun (gcmodule.c:2283)
==518217==    by 0x4A1E109: _PyObject_GC_NewVar (gcmodule.c:2318)
==518217==    by 0x4A1D636: PyTuple_New (tupleobject.c:75)
==518217==    by 0x4A2F0AB: r_object (marshal.c:1215)
==518217==    by 0x4A2F117: r_object (marshal.c:1221)
==518217==    by 0x4A2F3C9: r_object (marshal.c:1394)
==518217==    by 0x4A2F193: r_object (marshal.c:1221)
==518217==    by 0x4A2F3C9: r_object (marshal.c:1394)
==518217==    by 0x4A2F1EA: r_object (marshal.c:1221)
==518217==    by 0x4A2F3C9: r_object (marshal.c:1394)
==518217==    by 0x4AB87B3: read_object (marshal.c:1521)
==518217==
==518217== 48 bytes in 1 blocks are possibly lost in loss record 50 of 328
==518217==    at 0x484386F: malloc (vg_replace_malloc.c:393)
==518217==    by 0x4A15E02: UnknownInlinedFun (obmalloc.c:101)
==518217==    by 0x4A15E02: UnknownInlinedFun (obmalloc.c:586)
==518217==    by 0x4A15E02: UnknownInlinedFun (obmalloc.c:2003)
==518217==    by 0x4A15E02: UnknownInlinedFun (obmalloc.c:1996)
==518217==    by 0x4A15E02: PyObject_Malloc (obmalloc.c:712)
==518217==    by 0x4A1E109: UnknownInlinedFun (gcmodule.c:2283)
==518217==    by 0x4A1E109: _PyObject_GC_NewVar (gcmodule.c:2318)
==518217==    by 0x4A1FB3A: PyTuple_Pack.constprop.1 (tupleobject.c:166)
==518217==    by 0x4A1AF37: UnknownInlinedFun (typeobject.c:6125)
==518217==    by 0x4A1AF37: UnknownInlinedFun (typeobject.c:6465)
==518217==    by 0x4A1AF37: PyType_Ready (typeobject.c:6513)
==518217==    by 0x1326BCAF: UnknownInlinedFun (_datetimemodule.c:6744)
==518217==    by 0x1326BCAF: PyInit__datetime (_datetimemodule.c:6916)
==518217==    by 0x4AE60B0: UnknownInlinedFun (importdl.c:169)
==518217==    by 0x4AE60B0: UnknownInlinedFun (import.c:2385)
==518217==    by 0x4AE60B0: _imp_create_dynamic (import.c.h:446)
==518217==    by 0x4A4CA90: cfunction_vectorcall_FASTCALL (methodobject.c:427)
==518217==    by 0x4A3638A: _PyEval_EvalFrameDefault (ceval.c:5379)
==518217==    by 0x4A2DFC9: UnknownInlinedFun (pycore_ceval.h:73)
==518217==    by 0x4A2DFC9: _PyEval_Vector (ceval.c:6435)
==518217==    by 0x4A46915: UnknownInlinedFun (pycore_call.h:92)
==518217==    by 0x4A46915: object_vacall (call.c:819)
==518217==    by 0x4A6ABA3: PyObject_CallMethodObjArgs (call.c:879)
==518217==
==518217== 48 bytes in 1 blocks are possibly lost in loss record 51 of 328
==518217==    at 0x484386F: malloc (vg_replace_malloc.c:393)
==518217==    by 0x4A15E02: UnknownInlinedFun (obmalloc.c:101)
==518217==    by 0x4A15E02: UnknownInlinedFun (obmalloc.c:586)
==518217==    by 0x4A15E02: UnknownInlinedFun (obmalloc.c:2003)
==518217==    by 0x4A15E02: UnknownInlinedFun (obmalloc.c:1996)
==518217==    by 0x4A15E02: PyObject_Malloc (obmalloc.c:712)
==518217==    by 0x4A1E109: UnknownInlinedFun (gcmodule.c:2283)
==518217==    by 0x4A1E109: _PyObject_GC_NewVar (gcmodule.c:2318)
==518217==    by 0x4A1FB3A: PyTuple_Pack.constprop.1 (tupleobject.c:166)
==518217==    by 0x4AB5DB0: PyErr_NewException (errors.c:1167)
==518217==    by 0x1368D6E6: PyInit__socket (socketmodule.c:7242)
==518217==    by 0x4AE60B0: UnknownInlinedFun (importdl.c:169)
==518217==    by 0x4AE60B0: UnknownInlinedFun (import.c:2385)
==518217==    by 0x4AE60B0: _imp_create_dynamic (import.c.h:446)
==518217==    by 0x4A4CA90: cfunction_vectorcall_FASTCALL (methodobject.c:427)
==518217==    by 0x4A3638A: _PyEval_EvalFrameDefault (ceval.c:5379)
==518217==    by 0x4A2DFC9: UnknownInlinedFun (pycore_ceval.h:73)
==518217==    by 0x4A2DFC9: _PyEval_Vector (ceval.c:6435)
==518217==    by 0x4A46915: UnknownInlinedFun (pycore_call.h:92)
==518217==    by 0x4A46915: object_vacall (call.c:819)
==518217==    by 0x4A6ABA3: PyObject_CallMethodObjArgs (call.c:879)
==518217==
==518217== 48 bytes in 1 blocks are possibly lost in loss record 52 of 328
==518217==    at 0x484386F: malloc (vg_replace_malloc.c:393)
==518217==    by 0x4A15E02: UnknownInlinedFun (obmalloc.c:101)
==518217==    by 0x4A15E02: UnknownInlinedFun (obmalloc.c:586)
==518217==    by 0x4A15E02: UnknownInlinedFun (obmalloc.c:2003)
==518217==    by 0x4A15E02: UnknownInlinedFun (obmalloc.c:1996)
==518217==    by 0x4A15E02: PyObject_Malloc (obmalloc.c:712)
==518217==    by 0x4A1E109: UnknownInlinedFun (gcmodule.c:2283)
==518217==    by 0x4A1E109: _PyObject_GC_NewVar (gcmodule.c:2318)
==518217==    by 0x4A1FB3A: PyTuple_Pack.constprop.1 (tupleobject.c:166)
==518217==    by 0x4AB5DB0: PyErr_NewException (errors.c:1167)
==518217==    by 0x1368D71E: PyInit__socket (socketmodule.c:7248)
==518217==    by 0x4AE60B0: UnknownInlinedFun (importdl.c:169)
==518217==    by 0x4AE60B0: UnknownInlinedFun (import.c:2385)
==518217==    by 0x4AE60B0: _imp_create_dynamic (import.c.h:446)
==518217==    by 0x4A4CA90: cfunction_vectorcall_FASTCALL (methodobject.c:427)
==518217==    by 0x4A3638A: _PyEval_EvalFrameDefault (ceval.c:5379)
==518217==    by 0x4A2DFC9: UnknownInlinedFun (pycore_ceval.h:73)
==518217==    by 0x4A2DFC9: _PyEval_Vector (ceval.c:6435)
==518217==    by 0x4A46915: UnknownInlinedFun (pycore_call.h:92)
==518217==    by 0x4A46915: object_vacall (call.c:819)
==518217==    by 0x4A6ABA3: PyObject_CallMethodObjArgs (call.c:879)
==518217==
==518217== 48 bytes in 1 blocks are definitely lost in loss record 53 of 328
==518217==    at 0x484386F: malloc (vg_replace_malloc.c:393)
==518217==    by 0x4A15E02: UnknownInlinedFun (obmalloc.c:101)
==518217==    by 0x4A15E02: UnknownInlinedFun (obmalloc.c:586)
==518217==    by 0x4A15E02: UnknownInlinedFun (obmalloc.c:2003)
==518217==    by 0x4A15E02: UnknownInlinedFun (obmalloc.c:1996)
==518217==    by 0x4A15E02: PyObject_Malloc (obmalloc.c:712)
==518217==    by 0x4A1E109: UnknownInlinedFun (gcmodule.c:2283)
==518217==    by 0x4A1E109: _PyObject_GC_NewVar (gcmodule.c:2318)
==518217==    by 0x4A1D636: PyTuple_New (tupleobject.c:75)
==518217==    by 0x4A2F0AB: r_object (marshal.c:1215)
==518217==    by 0x4A2F1EA: r_object (marshal.c:1221)
==518217==    by 0x4A2F3C9: r_object (marshal.c:1394)
==518217==    by 0x4AB87B3: read_object (marshal.c:1521)
==518217==    by 0x4ADDEBE: UnknownInlinedFun (marshal.c:1828)
==518217==    by 0x4ADDEBE: marshal_loads (marshal.c.h:148)
==518217==    by 0x4A46484: cfunction_vectorcall_O (methodobject.c:514)
==518217==    by 0x4A3FD76: UnknownInlinedFun (pycore_call.h:92)
==518217==    by 0x4A3FD76: PyObject_Vectorcall (call.c:299)
==518217==    by 0x4A321A3: _PyEval_EvalFrameDefault (ceval.c:4772)
==518217==
==518217== 56 bytes in 1 blocks are possibly lost in loss record 77 of 328
==518217==    at 0x484386F: malloc (vg_replace_malloc.c:393)
==518217==    by 0x4A15E02: UnknownInlinedFun (obmalloc.c:101)
==518217==    by 0x4A15E02: UnknownInlinedFun (obmalloc.c:586)
==518217==    by 0x4A15E02: UnknownInlinedFun (obmalloc.c:2003)
==518217==    by 0x4A15E02: UnknownInlinedFun (obmalloc.c:1996)
==518217==    by 0x4A15E02: PyObject_Malloc (obmalloc.c:712)
==518217==    by 0x4A1E109: UnknownInlinedFun (gcmodule.c:2283)
==518217==    by 0x4A1E109: _PyObject_GC_NewVar (gcmodule.c:2318)
==518217==    by 0x4A1D636: PyTuple_New (tupleobject.c:75)
==518217==    by 0x4AB4060: mro_implementation (typeobject.c:1946)
==518217==    by 0x4AB3E5C: UnknownInlinedFun (typeobject.c:2083)
==518217==    by 0x4AB3E5C: mro_internal (typeobject.c:2140)
==518217==    by 0x4A19D14: UnknownInlinedFun (typeobject.c:6215)
==518217==    by 0x4A19D14: UnknownInlinedFun (typeobject.c:6468)
==518217==    by 0x4A19D14: PyType_Ready (typeobject.c:6513)
==518217==    by 0x4AB6332: UnknownInlinedFun (typeobject.c:3198)
==518217==    by 0x4AB6332: type_new (typeobject.c:3332)
==518217==    by 0x4A296EC: type_call (typeobject.c:1100)
==518217==    by 0x4A29592: _PyObject_MakeTpCall (call.c:214)
==518217==    by 0x4A2C43C: _PyObject_FastCallDictTstate (call.c:141)
==518217==    by 0x4AB9172: builtin___build_class__ (bltinmodule.c:209)
==518217==
==518217== 56 bytes in 1 blocks are possibly lost in loss record 78 of 328
==518217==    at 0x484386F: malloc (vg_replace_malloc.c:393)
==518217==    by 0x4A15E02: UnknownInlinedFun (obmalloc.c:101)
==518217==    by 0x4A15E02: UnknownInlinedFun (obmalloc.c:586)
==518217==    by 0x4A15E02: UnknownInlinedFun (obmalloc.c:2003)
==518217==    by 0x4A15E02: UnknownInlinedFun (obmalloc.c:1996)
==518217==    by 0x4A15E02: PyObject_Malloc (obmalloc.c:712)
==518217==    by 0x4A1E109: UnknownInlinedFun (gcmodule.c:2283)
==518217==    by 0x4A1E109: _PyObject_GC_NewVar (gcmodule.c:2318)
==518217==    by 0x4A571C5: UnknownInlinedFun (tupleobject.c:75)
==518217==    by 0x4A571C5: _PyStack_UnpackDict (call.c:984)
==518217==    by 0x4A2C32B: _PyObject_FastCallDictTstate (call.c:146)
==518217==    by 0x4A56ECB: UnknownInlinedFun (call.c:482)
==518217==    by 0x4A56ECB: slot_tp_init (typeobject.c:7861)
==518217==    by 0x4A2978A: type_call (typeobject.c:1112)
==518217==    by 0x4A29592: _PyObject_MakeTpCall (call.c:214)
==518217==    by 0x4A321A3: _PyEval_EvalFrameDefault (ceval.c:4772)
==518217==    by 0x4A2DFC9: UnknownInlinedFun (pycore_ceval.h:73)
==518217==    by 0x4A2DFC9: _PyEval_Vector (ceval.c:6435)
==518217==    by 0x4A46915: UnknownInlinedFun (pycore_call.h:92)
==518217==    by 0x4A46915: object_vacall (call.c:819)
==518217==    by 0x4A6ABA3: PyObject_CallMethodObjArgs (call.c:879)
==518217==
==518217== 56 bytes in 1 blocks are possibly lost in loss record 79 of 328
==518217==    at 0x484386F: malloc (vg_replace_malloc.c:393)
==518217==    by 0x4A15E02: UnknownInlinedFun (obmalloc.c:101)
==518217==    by 0x4A15E02: UnknownInlinedFun (obmalloc.c:586)
==518217==    by 0x4A15E02: UnknownInlinedFun (obmalloc.c:2003)
==518217==    by 0x4A15E02: UnknownInlinedFun (obmalloc.c:1996)
==518217==    by 0x4A15E02: PyObject_Malloc (obmalloc.c:712)
==518217==    by 0x4A1E109: UnknownInlinedFun (gcmodule.c:2283)
==518217==    by 0x4A1E109: _PyObject_GC_NewVar (gcmodule.c:2318)
==518217==    by 0x4A2E786: UnknownInlinedFun (tupleobject.c:401)
==518217==    by 0x4A2E786: UnknownInlinedFun (ceval.c:6181)
==518217==    by 0x4A2E786: _PyEvalFramePushAndInit (ceval.c:6376)
==518217==    by 0x4A38F0D: _PyEval_EvalFrameDefault (ceval.c:4745)
==518217==    by 0x4A2DFC9: UnknownInlinedFun (pycore_ceval.h:73)
==518217==    by 0x4A2DFC9: _PyEval_Vector (ceval.c:6435)
==518217==    by 0x4A46915: UnknownInlinedFun (pycore_call.h:92)
==518217==    by 0x4A46915: object_vacall (call.c:819)
==518217==    by 0x4A6ABA3: PyObject_CallMethodObjArgs (call.c:879)
==518217==    by 0x4A68349: UnknownInlinedFun (import.c:1736)
==518217==    by 0x4A68349: PyImport_ImportModuleLevelObject (import.c:1835)
==518217==    by 0x4A76249: UnknownInlinedFun (bltinmodule.c:277)
==518217==    by 0x4A76249: builtin___import__ (bltinmodule.c.h:78)
==518217==    by 0x4A3FE09: cfunction_vectorcall_FASTCALL_KEYWORDS (methodobject.c:443)
==518217==    by 0x4A3638A: _PyEval_EvalFrameDefault (ceval.c:5379)
==518217==
==518217== 56 bytes in 1 blocks are possibly lost in loss record 80 of 328
==518217==    at 0x484386F: malloc (vg_replace_malloc.c:393)
==518217==    by 0x4A15E02: UnknownInlinedFun (obmalloc.c:101)
==518217==    by 0x4A15E02: UnknownInlinedFun (obmalloc.c:586)
==518217==    by 0x4A15E02: UnknownInlinedFun (obmalloc.c:2003)
==518217==    by 0x4A15E02: UnknownInlinedFun (obmalloc.c:1996)
==518217==    by 0x4A15E02: PyObject_Malloc (obmalloc.c:712)
==518217==    by 0x4A1E109: UnknownInlinedFun (gcmodule.c:2283)
==518217==    by 0x4A1E109: _PyObject_GC_NewVar (gcmodule.c:2318)
==518217==    by 0x4A1D636: PyTuple_New (tupleobject.c:75)
==518217==    by 0x4A2F0AB: r_object (marshal.c:1215)
==518217==    by 0x4A2F3F1: r_object (marshal.c:1400)
==518217==    by 0x4A2F174: r_object (marshal.c:1221)
==518217==    by 0x4A2F3C9: r_object (marshal.c:1394)
==518217==    by 0x4A2F1EA: r_object (marshal.c:1221)
==518217==    by 0x4A2F3C9: r_object (marshal.c:1394)
==518217==    by 0x4AB87B3: read_object (marshal.c:1521)
==518217==    by 0x4ADDEBE: UnknownInlinedFun (marshal.c:1828)
==518217==    by 0x4ADDEBE: marshal_loads (marshal.c.h:148)
==518217==
==518217== 56 bytes in 1 blocks are possibly lost in loss record 81 of 328
==518217==    at 0x484386F: malloc (vg_replace_malloc.c:393)
==518217==    by 0x4A15E02: UnknownInlinedFun (obmalloc.c:101)
==518217==    by 0x4A15E02: UnknownInlinedFun (obmalloc.c:586)
==518217==    by 0x4A15E02: UnknownInlinedFun (obmalloc.c:2003)
==518217==    by 0x4A15E02: UnknownInlinedFun (obmalloc.c:1996)
==518217==    by 0x4A15E02: PyObject_Malloc (obmalloc.c:712)
==518217==    by 0x4A1E109: UnknownInlinedFun (gcmodule.c:2283)
==518217==    by 0x4A1E109: _PyObject_GC_NewVar (gcmodule.c:2318)
==518217==    by 0x4A1D636: PyTuple_New (tupleobject.c:75)
==518217==    by 0x4A2F0AB: r_object (marshal.c:1215)
==518217==    by 0x4A2F3F1: r_object (marshal.c:1400)
==518217==    by 0x4A2F193: r_object (marshal.c:1221)
==518217==    by 0x4A2F3C9: r_object (marshal.c:1394)
==518217==    by 0x4A2F1EA: r_object (marshal.c:1221)
==518217==    by 0x4A2F3C9: r_object (marshal.c:1394)
==518217==    by 0x4AB87B3: read_object (marshal.c:1521)
==518217==    by 0x4ADDEBE: UnknownInlinedFun (marshal.c:1828)
==518217==    by 0x4ADDEBE: marshal_loads (marshal.c.h:148)
==518217==
==518217== 56 bytes in 1 blocks are possibly lost in loss record 82 of 328
==518217==    at 0x484386F: malloc (vg_replace_malloc.c:393)
==518217==    by 0x4A15E02: UnknownInlinedFun (obmalloc.c:101)
==518217==    by 0x4A15E02: UnknownInlinedFun (obmalloc.c:586)
==518217==    by 0x4A15E02: UnknownInlinedFun (obmalloc.c:2003)
==518217==    by 0x4A15E02: UnknownInlinedFun (obmalloc.c:1996)
==518217==    by 0x4A15E02: PyObject_Malloc (obmalloc.c:712)
==518217==    by 0x4A1E109: UnknownInlinedFun (gcmodule.c:2283)
==518217==    by 0x4A1E109: _PyObject_GC_NewVar (gcmodule.c:2318)
==518217==    by 0x4A1D636: PyTuple_New (tupleobject.c:75)
==518217==    by 0x4A34416: _PyEval_EvalFrameDefault (ceval.c:3233)
==518217==    by 0x4A2DFC9: UnknownInlinedFun (pycore_ceval.h:73)
==518217==    by 0x4A2DFC9: _PyEval_Vector (ceval.c:6435)
==518217==    by 0x4AB7FAB: PyEval_EvalCode (ceval.c:1154)
==518217==    by 0x4AD0261: UnknownInlinedFun (bltinmodule.c:1075)
==518217==    by 0x4AD0261: builtin_exec (bltinmodule.c.h:465)
==518217==    by 0x4A3FE09: cfunction_vectorcall_FASTCALL_KEYWORDS (methodobject.c:443)
==518217==    by 0x4A3638A: _PyEval_EvalFrameDefault (ceval.c:5379)
==518217==    by 0x4A2DFC9: UnknownInlinedFun (pycore_ceval.h:73)
==518217==    by 0x4A2DFC9: _PyEval_Vector (ceval.c:6435)
==518217==    by 0x4A46915: UnknownInlinedFun (pycore_call.h:92)
==518217==    by 0x4A46915: object_vacall (call.c:819)
==518217==
==518217== 56 bytes in 1 blocks are possibly lost in loss record 83 of 328
==518217==    at 0x484386F: malloc (vg_replace_malloc.c:393)
==518217==    by 0x4A15E02: UnknownInlinedFun (obmalloc.c:101)
==518217==    by 0x4A15E02: UnknownInlinedFun (obmalloc.c:586)
==518217==    by 0x4A15E02: UnknownInlinedFun (obmalloc.c:2003)
==518217==    by 0x4A15E02: UnknownInlinedFun (obmalloc.c:1996)
==518217==    by 0x4A15E02: PyObject_Malloc (obmalloc.c:712)
==518217==    by 0x4A1E109: UnknownInlinedFun (gcmodule.c:2283)
==518217==    by 0x4A1E109: _PyObject_GC_NewVar (gcmodule.c:2318)
==518217==    by 0x4A91DD8: UnknownInlinedFun (tupleobject.c:75)
==518217==    by 0x4A91DD8: long_divmod (longobject.c:4263)
==518217==    by 0x4A4F0D0: binary_op1 (abstract.c:893)
==518217==    by 0x4A91D2D: UnknownInlinedFun (abstract.c:932)
==518217==    by 0x4A91D2D: UnknownInlinedFun (abstract.c:1068)
==518217==    by 0x4A91D2D: UnknownInlinedFun (bltinmodule.c:880)
==518217==    by 0x4A91D2D: builtin_divmod (bltinmodule.c.h:358)
==518217==    by 0x4A4CA90: cfunction_vectorcall_FASTCALL (methodobject.c:427)
==518217==    by 0x4A3FD76: UnknownInlinedFun (pycore_call.h:92)
==518217==    by 0x4A3FD76: PyObject_Vectorcall (call.c:299)
==518217==    by 0x4A321A3: _PyEval_EvalFrameDefault (ceval.c:4772)
==518217==    by 0x4A2DFC9: UnknownInlinedFun (pycore_ceval.h:73)
==518217==    by 0x4A2DFC9: _PyEval_Vector (ceval.c:6435)
==518217==    by 0x4A2C350: _PyObject_FastCallDictTstate (call.c:152)
==518217==    by 0x4A7DE8C: UnknownInlinedFun (call.c:482)
==518217==    by 0x4A7DE8C: slot_tp_new (typeobject.c:7891)
==518217==
==518217== 56 bytes in 1 blocks are possibly lost in loss record 84 of 328
==518217==    at 0x484386F: malloc (vg_replace_malloc.c:393)
==518217==    by 0x4A15E02: UnknownInlinedFun (obmalloc.c:101)
==518217==    by 0x4A15E02: UnknownInlinedFun (obmalloc.c:586)
==518217==    by 0x4A15E02: UnknownInlinedFun (obmalloc.c:2003)
==518217==    by 0x4A15E02: UnknownInlinedFun (obmalloc.c:1996)
==518217==    by 0x4A15E02: PyObject_Malloc (obmalloc.c:712)
==518217==    by 0x4A1E109: UnknownInlinedFun (gcmodule.c:2283)
==518217==    by 0x4A1E109: _PyObject_GC_NewVar (gcmodule.c:2318)
==518217==    by 0x4A91DD8: UnknownInlinedFun (tupleobject.c:75)
==518217==    by 0x4A91DD8: long_divmod (longobject.c:4263)
==518217==    by 0x4A4F0D0: binary_op1 (abstract.c:893)
==518217==    by 0x4A91D2D: UnknownInlinedFun (abstract.c:932)
==518217==    by 0x4A91D2D: UnknownInlinedFun (abstract.c:1068)
==518217==    by 0x4A91D2D: UnknownInlinedFun (bltinmodule.c:880)
==518217==    by 0x4A91D2D: builtin_divmod (bltinmodule.c.h:358)
==518217==    by 0x4A32F25: _PyEval_EvalFrameDefault (ceval.c:5053)
==518217==    by 0x4A2DFC9: UnknownInlinedFun (pycore_ceval.h:73)
==518217==    by 0x4A2DFC9: _PyEval_Vector (ceval.c:6435)
==518217==    by 0x4A2C350: _PyObject_FastCallDictTstate (call.c:152)
==518217==    by 0x4A7DE8C: UnknownInlinedFun (call.c:482)
==518217==    by 0x4A7DE8C: slot_tp_new (typeobject.c:7891)
==518217==    by 0x4A296EC: type_call (typeobject.c:1100)
==518217==    by 0x4A29592: _PyObject_MakeTpCall (call.c:214)
==518217==
==518217== 56 bytes in 1 blocks are possibly lost in loss record 85 of 328
==518217==    at 0x484386F: malloc (vg_replace_malloc.c:393)
==518217==    by 0x4A15E02: UnknownInlinedFun (obmalloc.c:101)
==518217==    by 0x4A15E02: UnknownInlinedFun (obmalloc.c:586)
==518217==    by 0x4A15E02: UnknownInlinedFun (obmalloc.c:2003)
==518217==    by 0x4A15E02: UnknownInlinedFun (obmalloc.c:1996)
==518217==    by 0x4A15E02: PyObject_Malloc (obmalloc.c:712)
==518217==    by 0x4A1E109: UnknownInlinedFun (gcmodule.c:2283)
==518217==    by 0x4A1E109: _PyObject_GC_NewVar (gcmodule.c:2318)
==518217==    by 0x4A1D636: PyTuple_New (tupleobject.c:75)
==518217==    by 0x4A34416: _PyEval_EvalFrameDefault (ceval.c:3233)
==518217==    by 0x4A2DFC9: UnknownInlinedFun (pycore_ceval.h:73)
==518217==    by 0x4A2DFC9: _PyEval_Vector (ceval.c:6435)
==518217==    by 0x4A5568C: UnknownInlinedFun (pycore_call.h:92)
==518217==    by 0x4A5568C: PyObject_CallOneArg (call.c:376)
==518217==    by 0x4A256CB: list_sort_impl (listobject.c:2317)
==518217==    by 0x4A63FD2: method_vectorcall_FASTCALL_KEYWORDS (descrobject.c:426)
==518217==    by 0x4A3FD76: UnknownInlinedFun (pycore_call.h:92)
==518217==    by 0x4A3FD76: PyObject_Vectorcall (call.c:299)
==518217==    by 0x4A321A3: _PyEval_EvalFrameDefault (ceval.c:4772)
==518217==    by 0x4A2DFC9: UnknownInlinedFun (pycore_ceval.h:73)
==518217==    by 0x4A2DFC9: _PyEval_Vector (ceval.c:6435)
==518217==
==518217== 56 bytes in 1 blocks are possibly lost in loss record 86 of 328
==518217==    at 0x484386F: malloc (vg_replace_malloc.c:393)
==518217==    by 0x4A15E02: UnknownInlinedFun (obmalloc.c:101)
==518217==    by 0x4A15E02: UnknownInlinedFun (obmalloc.c:586)
==518217==    by 0x4A15E02: UnknownInlinedFun (obmalloc.c:2003)
==518217==    by 0x4A15E02: UnknownInlinedFun (obmalloc.c:1996)
==518217==    by 0x4A15E02: PyObject_Malloc (obmalloc.c:712)
==518217==    by 0x4A1E109: UnknownInlinedFun (gcmodule.c:2283)
==518217==    by 0x4A1E109: _PyObject_GC_NewVar (gcmodule.c:2318)
==518217==    by 0x4A1D636: PyTuple_New (tupleobject.c:75)
==518217==    by 0x4A34416: _PyEval_EvalFrameDefault (ceval.c:3233)
==518217==    by 0x4A2DFC9: UnknownInlinedFun (pycore_ceval.h:73)
==518217==    by 0x4A2DFC9: _PyEval_Vector (ceval.c:6435)
==518217==    by 0x4A5568C: UnknownInlinedFun (pycore_call.h:92)
==518217==    by 0x4A5568C: PyObject_CallOneArg (call.c:376)
==518217==    by 0x4A256EE: list_sort_impl (listobject.c:2317)
==518217==    by 0x4A63FD2: method_vectorcall_FASTCALL_KEYWORDS (descrobject.c:426)
==518217==    by 0x4A3FD76: UnknownInlinedFun (pycore_call.h:92)
==518217==    by 0x4A3FD76: PyObject_Vectorcall (call.c:299)
==518217==    by 0x4A321A3: _PyEval_EvalFrameDefault (ceval.c:4772)
==518217==    by 0x4A2DFC9: UnknownInlinedFun (pycore_ceval.h:73)
==518217==    by 0x4A2DFC9: _PyEval_Vector (ceval.c:6435)
==518217==
==518217== 56 bytes in 1 blocks are possibly lost in loss record 87 of 328
==518217==    at 0x484386F: malloc (vg_replace_malloc.c:393)
==518217==    by 0x4A15E02: UnknownInlinedFun (obmalloc.c:101)
==518217==    by 0x4A15E02: UnknownInlinedFun (obmalloc.c:586)
==518217==    by 0x4A15E02: UnknownInlinedFun (obmalloc.c:2003)
==518217==    by 0x4A15E02: UnknownInlinedFun (obmalloc.c:1996)
==518217==    by 0x4A15E02: PyObject_Malloc (obmalloc.c:712)
==518217==    by 0x4A1E109: UnknownInlinedFun (gcmodule.c:2283)
==518217==    by 0x4A1E109: _PyObject_GC_NewVar (gcmodule.c:2318)
==518217==    by 0x4A1D636: PyTuple_New (tupleobject.c:75)
==518217==    by 0x4A34416: _PyEval_EvalFrameDefault (ceval.c:3233)
==518217==    by 0x4A2DFC9: UnknownInlinedFun (pycore_ceval.h:73)
==518217==    by 0x4A2DFC9: _PyEval_Vector (ceval.c:6435)
==518217==    by 0x4A5568C: UnknownInlinedFun (pycore_call.h:92)
==518217==    by 0x4A5568C: PyObject_CallOneArg (call.c:376)
==518217==    by 0x4A2570D: list_sort_impl (listobject.c:2317)
==518217==    by 0x4A63FD2: method_vectorcall_FASTCALL_KEYWORDS (descrobject.c:426)
==518217==    by 0x4A3FD76: UnknownInlinedFun (pycore_call.h:92)
==518217==    by 0x4A3FD76: PyObject_Vectorcall (call.c:299)
==518217==    by 0x4A321A3: _PyEval_EvalFrameDefault (ceval.c:4772)
==518217==    by 0x4A2DFC9: UnknownInlinedFun (pycore_ceval.h:73)
==518217==    by 0x4A2DFC9: _PyEval_Vector (ceval.c:6435)
==518217==
==518217== 64 bytes in 1 blocks are possibly lost in loss record 135 of 328
==518217==    at 0x484386F: malloc (vg_replace_malloc.c:393)
==518217==    by 0x4A15E02: UnknownInlinedFun (obmalloc.c:101)
==518217==    by 0x4A15E02: UnknownInlinedFun (obmalloc.c:586)
==518217==    by 0x4A15E02: UnknownInlinedFun (obmalloc.c:2003)
==518217==    by 0x4A15E02: UnknownInlinedFun (obmalloc.c:1996)
==518217==    by 0x4A15E02: PyObject_Malloc (obmalloc.c:712)
==518217==    by 0x4A15BAF: UnknownInlinedFun (gcmodule.c:2283)
==518217==    by 0x4A15BAF: _PyObject_GC_New (gcmodule.c:2298)
==518217==    by 0x4A166C3: UnknownInlinedFun (dictobject.c:737)
==518217==    by 0x4A166C3: PyDict_New (dictobject.c:841)
==518217==    by 0x4AB4DB4: new_module_notrack (moduleobject.c:91)
==518217==    by 0x4AB4D55: PyModule_NewObject (moduleobject.c:112)
==518217==    by 0x4AB4D1B: PyModule_New (moduleobject.c:132)
==518217==    by 0x4AB4C48: _PyModule_CreateInitialized (moduleobject.c:230)
==518217==    by 0x4AAF260: UnknownInlinedFun (bltinmodule.c:3024)
==518217==    by 0x4AAF260: UnknownInlinedFun (pylifecycle.c:766)
==518217==    by 0x4AAF260: pycore_interp_init (pylifecycle.c:864)
==518217==    by 0x4AA96E1: UnknownInlinedFun (pylifecycle.c:901)
==518217==    by 0x4AA96E1: pyinit_core.constprop.0 (pylifecycle.c:1064)
==518217==    by 0x4AA9339: Py_InitializeFromConfig (pylifecycle.c:1254)
==518217==    by 0x4AA8F13: pymain_init (main.c:67)
==518217==
==518217== 64 bytes in 1 blocks are possibly lost in loss record 136 of 328
==518217==    at 0x484386F: malloc (vg_replace_malloc.c:393)
==518217==    by 0x4A15E02: UnknownInlinedFun (obmalloc.c:101)
==518217==    by 0x4A15E02: UnknownInlinedFun (obmalloc.c:586)
==518217==    by 0x4A15E02: UnknownInlinedFun (obmalloc.c:2003)
==518217==    by 0x4A15E02: UnknownInlinedFun (obmalloc.c:1996)
==518217==    by 0x4A15E02: PyObject_Malloc (obmalloc.c:712)
==518217==    by 0x4A1E109: UnknownInlinedFun (gcmodule.c:2283)
==518217==    by 0x4A1E109: _PyObject_GC_NewVar (gcmodule.c:2318)
==518217==    by 0x4A1DECC: _PyTuple_FromArray (tupleobject.c:381)
==518217==    by 0x4AB67AF: UnknownInlinedFun (typeobject.c:2634)
==518217==    by 0x4AB67AF: UnknownInlinedFun (typeobject.c:2703)
==518217==    by 0x4AB67AF: UnknownInlinedFun (typeobject.c:2738)
==518217==    by 0x4AB67AF: UnknownInlinedFun (typeobject.c:3161)
==518217==    by 0x4AB67AF: UnknownInlinedFun (typeobject.c:3188)
==518217==    by 0x4AB67AF: type_new (typeobject.c:3332)
==518217==    by 0x4A296EC: type_call (typeobject.c:1100)
==518217==    by 0x4A29592: _PyObject_MakeTpCall (call.c:214)
==518217==    by 0x4A2C43C: _PyObject_FastCallDictTstate (call.c:141)
==518217==    by 0x4AB9172: builtin___build_class__ (bltinmodule.c:209)
==518217==    by 0x4A3FE09: cfunction_vectorcall_FASTCALL_KEYWORDS (methodobject.c:443)
==518217==    by 0x4A3FD76: UnknownInlinedFun (pycore_call.h:92)
==518217==    by 0x4A3FD76: PyObject_Vectorcall (call.c:299)
==518217==    by 0x4A321A3: _PyEval_EvalFrameDefault (ceval.c:4772)
==518217==
==518217== 64 bytes in 1 blocks are possibly lost in loss record 137 of 328
==518217==    at 0x484386F: malloc (vg_replace_malloc.c:393)
==518217==    by 0x4A15E02: UnknownInlinedFun (obmalloc.c:101)
==518217==    by 0x4A15E02: UnknownInlinedFun (obmalloc.c:586)
==518217==    by 0x4A15E02: UnknownInlinedFun (obmalloc.c:2003)
==518217==    by 0x4A15E02: UnknownInlinedFun (obmalloc.c:1996)
==518217==    by 0x4A15E02: PyObject_Malloc (obmalloc.c:712)
==518217==    by 0x4A1E109: UnknownInlinedFun (gcmodule.c:2283)
==518217==    by 0x4A1E109: _PyObject_GC_NewVar (gcmodule.c:2318)
==518217==    by 0x4A1D636: PyTuple_New (tupleobject.c:75)
==518217==    by 0x4A34416: _PyEval_EvalFrameDefault (ceval.c:3233)
==518217==    by 0x4A2DFC9: UnknownInlinedFun (pycore_ceval.h:73)
==518217==    by 0x4A2DFC9: _PyEval_Vector (ceval.c:6435)
==518217==    by 0x4A2C350: _PyObject_FastCallDictTstate (call.c:152)
==518217==    by 0x4A7DE8C: UnknownInlinedFun (call.c:482)
==518217==    by 0x4A7DE8C: slot_tp_new (typeobject.c:7891)
==518217==    by 0x4A296EC: type_call (typeobject.c:1100)
==518217==    by 0x4A29592: _PyObject_MakeTpCall (call.c:214)
==518217==    by 0x4A321A3: _PyEval_EvalFrameDefault (ceval.c:4772)
==518217==    by 0x4A2DFC9: UnknownInlinedFun (pycore_ceval.h:73)
==518217==    by 0x4A2DFC9: _PyEval_Vector (ceval.c:6435)
==518217==
==518217== 64 bytes in 1 blocks are possibly lost in loss record 138 of 328
==518217==    at 0x484386F: malloc (vg_replace_malloc.c:393)
==518217==    by 0x4A15E02: UnknownInlinedFun (obmalloc.c:101)
==518217==    by 0x4A15E02: UnknownInlinedFun (obmalloc.c:586)
==518217==    by 0x4A15E02: UnknownInlinedFun (obmalloc.c:2003)
==518217==    by 0x4A15E02: UnknownInlinedFun (obmalloc.c:1996)
==518217==    by 0x4A15E02: PyObject_Malloc (obmalloc.c:712)
==518217==    by 0x4A1E109: UnknownInlinedFun (gcmodule.c:2283)
==518217==    by 0x4A1E109: _PyObject_GC_NewVar (gcmodule.c:2318)
==518217==    by 0x4A1D636: PyTuple_New (tupleobject.c:75)
==518217==    by 0x4AB4060: mro_implementation (typeobject.c:1946)
==518217==    by 0x4AB3E5C: UnknownInlinedFun (typeobject.c:2083)
==518217==    by 0x4AB3E5C: mro_internal (typeobject.c:2140)
==518217==    by 0x4A19D14: UnknownInlinedFun (typeobject.c:6215)
==518217==    by 0x4A19D14: UnknownInlinedFun (typeobject.c:6468)
==518217==    by 0x4A19D14: PyType_Ready (typeobject.c:6513)
==518217==    by 0x1326BCAF: UnknownInlinedFun (_datetimemodule.c:6744)
==518217==    by 0x1326BCAF: PyInit__datetime (_datetimemodule.c:6916)
==518217==    by 0x4AE60B0: UnknownInlinedFun (importdl.c:169)
==518217==    by 0x4AE60B0: UnknownInlinedFun (import.c:2385)
==518217==    by 0x4AE60B0: _imp_create_dynamic (import.c.h:446)
==518217==    by 0x4A4CA90: cfunction_vectorcall_FASTCALL (methodobject.c:427)
==518217==    by 0x4A3638A: _PyEval_EvalFrameDefault (ceval.c:5379)
==518217==    by 0x4A2DFC9: UnknownInlinedFun (pycore_ceval.h:73)
==518217==    by 0x4A2DFC9: _PyEval_Vector (ceval.c:6435)
==518217==
==518217== 64 bytes in 1 blocks are possibly lost in loss record 139 of 328
==518217==    at 0x484386F: malloc (vg_replace_malloc.c:393)
==518217==    by 0x4A15E02: UnknownInlinedFun (obmalloc.c:101)
==518217==    by 0x4A15E02: UnknownInlinedFun (obmalloc.c:586)
==518217==    by 0x4A15E02: UnknownInlinedFun (obmalloc.c:2003)
==518217==    by 0x4A15E02: UnknownInlinedFun (obmalloc.c:1996)
==518217==    by 0x4A15E02: PyObject_Malloc (obmalloc.c:712)
==518217==    by 0x4A15BAF: UnknownInlinedFun (gcmodule.c:2283)
==518217==    by 0x4A15BAF: _PyObject_GC_New (gcmodule.c:2298)
==518217==    by 0x4A166C3: UnknownInlinedFun (dictobject.c:737)
==518217==    by 0x4A166C3: PyDict_New (dictobject.c:841)
==518217==    by 0x4AB4DB4: new_module_notrack (moduleobject.c:91)
==518217==    by 0x4AB4D55: PyModule_NewObject (moduleobject.c:112)
==518217==    by 0x4AB79A5: import_add_module (import.c:587)
==518217==    by 0x4ABC4FC: PyImport_AddModuleObject (import.c:602)
==518217==    by 0x4ABBBEB: PyImport_AddModule (import.c:623)
==518217==    by 0x13F6EFC7: __pyx_pymod_exec_cysimdjson(_object*) (cysimdjson.cpp:8733)
==518217==    by 0x4ABE182: PyModule_ExecDef (moduleobject.c:419)
==518217==    by 0x4AC4A5C: UnknownInlinedFun (import.c:2426)
==518217==    by 0x4AC4A5C: _imp_exec_builtin (import.c.h:504)
==518217==
==518217== 64 bytes in 1 blocks are definitely lost in loss record 142 of 328
==518217==    at 0x484386F: malloc (vg_replace_malloc.c:393)
==518217==    by 0x4A15E02: UnknownInlinedFun (obmalloc.c:101)
==518217==    by 0x4A15E02: UnknownInlinedFun (obmalloc.c:586)
==518217==    by 0x4A15E02: UnknownInlinedFun (obmalloc.c:2003)
==518217==    by 0x4A15E02: UnknownInlinedFun (obmalloc.c:1996)
==518217==    by 0x4A15E02: PyObject_Malloc (obmalloc.c:712)
==518217==    by 0x4A1E109: UnknownInlinedFun (gcmodule.c:2283)
==518217==    by 0x4A1E109: _PyObject_GC_NewVar (gcmodule.c:2318)
==518217==    by 0x4A1D636: PyTuple_New (tupleobject.c:75)
==518217==    by 0x4A2F0AB: r_object (marshal.c:1215)
==518217==    by 0x4A2F3C9: r_object (marshal.c:1394)
==518217==    by 0x4A2F1EA: r_object (marshal.c:1221)
==518217==    by 0x4A2F3C9: r_object (marshal.c:1394)
==518217==    by 0x4A2F1EA: r_object (marshal.c:1221)
==518217==    by 0x4A2F3C9: r_object (marshal.c:1394)
==518217==    by 0x4AB87B3: read_object (marshal.c:1521)
==518217==    by 0x4ADDEBE: UnknownInlinedFun (marshal.c:1828)
==518217==    by 0x4ADDEBE: marshal_loads (marshal.c.h:148)
==518217==
==518217== 96 bytes in 1 blocks are possibly lost in loss record 174 of 328
==518217==    at 0x484386F: malloc (vg_replace_malloc.c:393)
==518217==    by 0x4A15E02: UnknownInlinedFun (obmalloc.c:101)
==518217==    by 0x4A15E02: UnknownInlinedFun (obmalloc.c:586)
==518217==    by 0x4A15E02: UnknownInlinedFun (obmalloc.c:2003)
==518217==    by 0x4A15E02: UnknownInlinedFun (obmalloc.c:1996)
==518217==    by 0x4A15E02: PyObject_Malloc (obmalloc.c:712)
==518217==    by 0x4A1EEDE: _PyType_AllocNoTrack (typeobject.c:1133)
==518217==    by 0x4A1EE2C: PyType_GenericAlloc (typeobject.c:1157)
==518217==    by 0x13F716CF: __pyx_tp_new_10cysimdjson_10cysimdjson___pyx_scope_struct_1_items(_typeobject*, _object*, _object*) (cysimdjson.cpp:7811)
==518217==    by 0x13F749B1: __pyx_pf_10cysimdjson_10cysimdjson_10JSONObject_5items (cysimdjson.cpp:2215)
==518217==    by 0x13F749B1: __pyx_pw_10cysimdjson_10cysimdjson_10JSONObject_6items(_object*, _object*) (cysimdjson.cpp:2200)
==518217==    by 0x4A52CA9: method_vectorcall_NOARGS (descrobject.c:453)
==518217==    by 0x4A3FD76: UnknownInlinedFun (pycore_call.h:92)
==518217==    by 0x4A3FD76: PyObject_Vectorcall (call.c:299)
==518217==    by 0x4A321A3: _PyEval_EvalFrameDefault (ceval.c:4772)
==518217==    by 0x4A2DFC9: UnknownInlinedFun (pycore_ceval.h:73)
==518217==    by 0x4A2DFC9: _PyEval_Vector (ceval.c:6435)
==518217==    by 0x4AB7FAB: PyEval_EvalCode (ceval.c:1154)
==518217==    by 0x4AD7152: run_eval_code_obj (pythonrun.c:1714)
==518217==
==518217== 96 bytes in 2 blocks are possibly lost in loss record 175 of 328
==518217==    at 0x484386F: malloc (vg_replace_malloc.c:393)
==518217==    by 0x4A15E02: UnknownInlinedFun (obmalloc.c:101)
==518217==    by 0x4A15E02: UnknownInlinedFun (obmalloc.c:586)
==518217==    by 0x4A15E02: UnknownInlinedFun (obmalloc.c:2003)
==518217==    by 0x4A15E02: UnknownInlinedFun (obmalloc.c:1996)
==518217==    by 0x4A15E02: PyObject_Malloc (obmalloc.c:712)
==518217==    by 0x4A1E109: UnknownInlinedFun (gcmodule.c:2283)
==518217==    by 0x4A1E109: _PyObject_GC_NewVar (gcmodule.c:2318)
==518217==    by 0x4A1FB3A: PyTuple_Pack.constprop.1 (tupleobject.c:166)
==518217==    by 0x4A1AF37: UnknownInlinedFun (typeobject.c:6125)
==518217==    by 0x4A1AF37: UnknownInlinedFun (typeobject.c:6465)
==518217==    by 0x4A1AF37: PyType_Ready (typeobject.c:6513)
==518217==    by 0x4AADD91: UnknownInlinedFun (object.c:1986)
==518217==    by 0x4AADD91: UnknownInlinedFun (pylifecycle.c:704)
==518217==    by 0x4AADD91: pycore_interp_init (pylifecycle.c:845)
==518217==    by 0x4AA96E1: UnknownInlinedFun (pylifecycle.c:901)
==518217==    by 0x4AA96E1: pyinit_core.constprop.0 (pylifecycle.c:1064)
==518217==    by 0x4AA9339: Py_InitializeFromConfig (pylifecycle.c:1254)
==518217==    by 0x4AA8F13: pymain_init (main.c:67)
==518217==    by 0x4AA818F: pymain_main (main.c:701)
==518217==    by 0x4AA7E6A: Py_BytesMain (main.c:734)
==518217==    by 0x4DFA50F: (below main) (libc_start_call_main.h:58)
==518217==
==518217== 96 bytes in 2 blocks are possibly lost in loss record 176 of 328
==518217==    at 0x484386F: malloc (vg_replace_malloc.c:393)
==518217==    by 0x4A15E02: UnknownInlinedFun (obmalloc.c:101)
==518217==    by 0x4A15E02: UnknownInlinedFun (obmalloc.c:586)
==518217==    by 0x4A15E02: UnknownInlinedFun (obmalloc.c:2003)
==518217==    by 0x4A15E02: UnknownInlinedFun (obmalloc.c:1996)
==518217==    by 0x4A15E02: PyObject_Malloc (obmalloc.c:712)
==518217==    by 0x4A1E109: UnknownInlinedFun (gcmodule.c:2283)
==518217==    by 0x4A1E109: _PyObject_GC_NewVar (gcmodule.c:2318)
==518217==    by 0x4A1FB3A: PyTuple_Pack.constprop.1 (tupleobject.c:166)
==518217==    by 0x4AB65DA: UnknownInlinedFun (typeobject.c:3230)
==518217==    by 0x4AB65DA: type_new (typeobject.c:3320)
==518217==    by 0x4A296EC: type_call (typeobject.c:1100)
==518217==    by 0x4A29592: _PyObject_MakeTpCall (call.c:214)
==518217==    by 0x4A2C43C: _PyObject_FastCallDictTstate (call.c:141)
==518217==    by 0x4AB9172: builtin___build_class__ (bltinmodule.c:209)
==518217==    by 0x4A3FE09: cfunction_vectorcall_FASTCALL_KEYWORDS (methodobject.c:443)
==518217==    by 0x4A3FD76: UnknownInlinedFun (pycore_call.h:92)
==518217==    by 0x4A3FD76: PyObject_Vectorcall (call.c:299)
==518217==    by 0x4A321A3: _PyEval_EvalFrameDefault (ceval.c:4772)
==518217==
==518217== 104 bytes in 2 blocks are possibly lost in loss record 177 of 328
==518217==    at 0x484386F: malloc (vg_replace_malloc.c:393)
==518217==    by 0x4A15E02: UnknownInlinedFun (obmalloc.c:101)
==518217==    by 0x4A15E02: UnknownInlinedFun (obmalloc.c:586)
==518217==    by 0x4A15E02: UnknownInlinedFun (obmalloc.c:2003)
==518217==    by 0x4A15E02: UnknownInlinedFun (obmalloc.c:1996)
==518217==    by 0x4A15E02: PyObject_Malloc (obmalloc.c:712)
==518217==    by 0x4A1E109: UnknownInlinedFun (gcmodule.c:2283)
==518217==    by 0x4A1E109: _PyObject_GC_NewVar (gcmodule.c:2318)
==518217==    by 0x4A1DECC: _PyTuple_FromArray (tupleobject.c:381)
==518217==    by 0x4A29561: _PyObject_MakeTpCall (call.c:188)
==518217==    by 0x4A321A3: _PyEval_EvalFrameDefault (ceval.c:4772)
==518217==    by 0x4A2DFC9: UnknownInlinedFun (pycore_ceval.h:73)
==518217==    by 0x4A2DFC9: _PyEval_Vector (ceval.c:6435)
==518217==    by 0x4AB9134: builtin___build_class__ (bltinmodule.c:201)
==518217==    by 0x4A3FE09: cfunction_vectorcall_FASTCALL_KEYWORDS (methodobject.c:443)
==518217==    by 0x4A3FD76: UnknownInlinedFun (pycore_call.h:92)
==518217==    by 0x4A3FD76: PyObject_Vectorcall (call.c:299)
==518217==    by 0x4A321A3: _PyEval_EvalFrameDefault (ceval.c:4772)
==518217==    by 0x4A2DFC9: UnknownInlinedFun (pycore_ceval.h:73)
==518217==    by 0x4A2DFC9: _PyEval_Vector (ceval.c:6435)
==518217==
==518217== 112 bytes in 2 blocks are possibly lost in loss record 182 of 328
==518217==    at 0x484386F: malloc (vg_replace_malloc.c:393)
==518217==    by 0x4A15E02: UnknownInlinedFun (obmalloc.c:101)
==518217==    by 0x4A15E02: UnknownInlinedFun (obmalloc.c:586)
==518217==    by 0x4A15E02: UnknownInlinedFun (obmalloc.c:2003)
==518217==    by 0x4A15E02: UnknownInlinedFun (obmalloc.c:1996)
==518217==    by 0x4A15E02: PyObject_Malloc (obmalloc.c:712)
==518217==    by 0x4A1E109: UnknownInlinedFun (gcmodule.c:2283)
==518217==    by 0x4A1E109: _PyObject_GC_NewVar (gcmodule.c:2318)
==518217==    by 0x4A1D636: PyTuple_New (tupleobject.c:75)
==518217==    by 0x4AB4060: mro_implementation (typeobject.c:1946)
==518217==    by 0x4AB3E5C: UnknownInlinedFun (typeobject.c:2083)
==518217==    by 0x4AB3E5C: mro_internal (typeobject.c:2140)
==518217==    by 0x4A19D14: UnknownInlinedFun (typeobject.c:6215)
==518217==    by 0x4A19D14: UnknownInlinedFun (typeobject.c:6468)
==518217==    by 0x4A19D14: PyType_Ready (typeobject.c:6513)
==518217==    by 0x4AADD91: UnknownInlinedFun (object.c:1986)
==518217==    by 0x4AADD91: UnknownInlinedFun (pylifecycle.c:704)
==518217==    by 0x4AADD91: pycore_interp_init (pylifecycle.c:845)
==518217==    by 0x4AA96E1: UnknownInlinedFun (pylifecycle.c:901)
==518217==    by 0x4AA96E1: pyinit_core.constprop.0 (pylifecycle.c:1064)
==518217==    by 0x4AA9339: Py_InitializeFromConfig (pylifecycle.c:1254)
==518217==    by 0x4AA8F13: pymain_init (main.c:67)
==518217==    by 0x4AA818F: pymain_main (main.c:701)
==518217==
==518217== 112 bytes in 2 blocks are possibly lost in loss record 183 of 328
==518217==    at 0x484386F: malloc (vg_replace_malloc.c:393)
==518217==    by 0x4A15E02: UnknownInlinedFun (obmalloc.c:101)
==518217==    by 0x4A15E02: UnknownInlinedFun (obmalloc.c:586)
==518217==    by 0x4A15E02: UnknownInlinedFun (obmalloc.c:2003)
==518217==    by 0x4A15E02: UnknownInlinedFun (obmalloc.c:1996)
==518217==    by 0x4A15E02: PyObject_Malloc (obmalloc.c:712)
==518217==    by 0x4A1E109: UnknownInlinedFun (gcmodule.c:2283)
==518217==    by 0x4A1E109: _PyObject_GC_NewVar (gcmodule.c:2318)
==518217==    by 0x4A2E786: UnknownInlinedFun (tupleobject.c:401)
==518217==    by 0x4A2E786: UnknownInlinedFun (ceval.c:6181)
==518217==    by 0x4A2E786: _PyEvalFramePushAndInit (ceval.c:6376)
==518217==    by 0x4A38F0D: _PyEval_EvalFrameDefault (ceval.c:4745)
==518217==    by 0x4A2DFC9: UnknownInlinedFun (pycore_ceval.h:73)
==518217==    by 0x4A2DFC9: _PyEval_Vector (ceval.c:6435)
==518217==    by 0x4A46915: UnknownInlinedFun (pycore_call.h:92)
==518217==    by 0x4A46915: object_vacall (call.c:819)
==518217==    by 0x4A6ABA3: PyObject_CallMethodObjArgs (call.c:879)
==518217==    by 0x4A68349: UnknownInlinedFun (import.c:1736)
==518217==    by 0x4A68349: PyImport_ImportModuleLevelObject (import.c:1835)
==518217==    by 0x4A3795D: UnknownInlinedFun (ceval.c:7425)
==518217==    by 0x4A3795D: _PyEval_EvalFrameDefault (ceval.c:3949)
==518217==    by 0x4A2DFC9: UnknownInlinedFun (pycore_ceval.h:73)
==518217==    by 0x4A2DFC9: _PyEval_Vector (ceval.c:6435)
==518217==    by 0x4AB7FAB: PyEval_EvalCode (ceval.c:1154)
==518217==
==518217== 112 bytes in 2 blocks are possibly lost in loss record 184 of 328
==518217==    at 0x484386F: malloc (vg_replace_malloc.c:393)
==518217==    by 0x4A15E02: UnknownInlinedFun (obmalloc.c:101)
==518217==    by 0x4A15E02: UnknownInlinedFun (obmalloc.c:586)
==518217==    by 0x4A15E02: UnknownInlinedFun (obmalloc.c:2003)
==518217==    by 0x4A15E02: UnknownInlinedFun (obmalloc.c:1996)
==518217==    by 0x4A15E02: PyObject_Malloc (obmalloc.c:712)
==518217==    by 0x4A1E109: UnknownInlinedFun (gcmodule.c:2283)
==518217==    by 0x4A1E109: _PyObject_GC_NewVar (gcmodule.c:2318)
==518217==    by 0x4A1D636: PyTuple_New (tupleobject.c:75)
==518217==    by 0x4AB4060: mro_implementation (typeobject.c:1946)
==518217==    by 0x4AB3E5C: UnknownInlinedFun (typeobject.c:2083)
==518217==    by 0x4AB3E5C: mro_internal (typeobject.c:2140)
==518217==    by 0x4A19D14: UnknownInlinedFun (typeobject.c:6215)
==518217==    by 0x4A19D14: UnknownInlinedFun (typeobject.c:6468)
==518217==    by 0x4A19D14: PyType_Ready (typeobject.c:6513)
==518217==    by 0x4AC51E5: PyModule_AddType (modsupport.c:706)
==518217==    by 0x1326BC91: UnknownInlinedFun (_datetimemodule.c:6739)
==518217==    by 0x1326BC91: PyInit__datetime (_datetimemodule.c:6916)
==518217==    by 0x4AE60B0: UnknownInlinedFun (importdl.c:169)
==518217==    by 0x4AE60B0: UnknownInlinedFun (import.c:2385)
==518217==    by 0x4AE60B0: _imp_create_dynamic (import.c.h:446)
==518217==    by 0x4A4CA90: cfunction_vectorcall_FASTCALL (methodobject.c:427)
==518217==    by 0x4A3638A: _PyEval_EvalFrameDefault (ceval.c:5379)
==518217==
==518217== 120 bytes in 1 blocks are possibly lost in loss record 196 of 328
==518217==    at 0x484386F: malloc (vg_replace_malloc.c:393)
==518217==    by 0x4A15E02: UnknownInlinedFun (obmalloc.c:101)
==518217==    by 0x4A15E02: UnknownInlinedFun (obmalloc.c:586)
==518217==    by 0x4A15E02: UnknownInlinedFun (obmalloc.c:2003)
==518217==    by 0x4A15E02: UnknownInlinedFun (obmalloc.c:1996)
==518217==    by 0x4A15E02: PyObject_Malloc (obmalloc.c:712)
==518217==    by 0x4A280D7: clone_combined_dict_keys (dictobject.c:790)
==518217==    by 0x4A27D4E: dict_merge (dictobject.c:2850)
==518217==    by 0x4A36C52: UnknownInlinedFun (dictobject.c:3003)
==518217==    by 0x4A36C52: _PyEval_EvalFrameDefault (ceval.c:3435)
==518217==    by 0x4A2DFC9: UnknownInlinedFun (pycore_ceval.h:73)
==518217==    by 0x4A2DFC9: _PyEval_Vector (ceval.c:6435)
==518217==    by 0x4A46915: UnknownInlinedFun (pycore_call.h:92)
==518217==    by 0x4A46915: object_vacall (call.c:819)
==518217==    by 0x4A6ABA3: PyObject_CallMethodObjArgs (call.c:879)
==518217==    by 0x4A68349: UnknownInlinedFun (import.c:1736)
==518217==    by 0x4A68349: PyImport_ImportModuleLevelObject (import.c:1835)
==518217==    by 0x4A3795D: UnknownInlinedFun (ceval.c:7425)
==518217==    by 0x4A3795D: _PyEval_EvalFrameDefault (ceval.c:3949)
==518217==    by 0x4A2DFC9: UnknownInlinedFun (pycore_ceval.h:73)
==518217==    by 0x4A2DFC9: _PyEval_Vector (ceval.c:6435)
==518217==    by 0x4AB7FAB: PyEval_EvalCode (ceval.c:1154)
==518217==
==518217== 120 bytes in 2 blocks are possibly lost in loss record 197 of 328
==518217==    at 0x484386F: malloc (vg_replace_malloc.c:393)
==518217==    by 0x4A15E02: UnknownInlinedFun (obmalloc.c:101)
==518217==    by 0x4A15E02: UnknownInlinedFun (obmalloc.c:586)
==518217==    by 0x4A15E02: UnknownInlinedFun (obmalloc.c:2003)
==518217==    by 0x4A15E02: UnknownInlinedFun (obmalloc.c:1996)
==518217==    by 0x4A15E02: PyObject_Malloc (obmalloc.c:712)
==518217==    by 0x4A1E109: UnknownInlinedFun (gcmodule.c:2283)
==518217==    by 0x4A1E109: _PyObject_GC_NewVar (gcmodule.c:2318)
==518217==    by 0x4A1DECC: _PyTuple_FromArray (tupleobject.c:381)
==518217==    by 0x4A29561: _PyObject_MakeTpCall (call.c:188)
==518217==    by 0x4A321A3: _PyEval_EvalFrameDefault (ceval.c:4772)
==518217==    by 0x4A2DFC9: UnknownInlinedFun (pycore_ceval.h:73)
==518217==    by 0x4A2DFC9: _PyEval_Vector (ceval.c:6435)
==518217==    by 0x4A6C26F: UnknownInlinedFun (call.c:393)
==518217==    by 0x4A6C26F: UnknownInlinedFun (pycore_call.h:92)
==518217==    by 0x4A6C26F: method_vectorcall (classobject.c:67)
==518217==    by 0x4A36A75: UnknownInlinedFun (pycore_call.h:92)
==518217==    by 0x4A36A75: UnknownInlinedFun (pycore_call.h:107)
==518217==    by 0x4A36A75: _PyEval_EvalFrameDefault (ceval.c:4425)
==518217==    by 0x4A2DFC9: UnknownInlinedFun (pycore_ceval.h:73)
==518217==    by 0x4A2DFC9: _PyEval_Vector (ceval.c:6435)
==518217==    by 0x4A46915: UnknownInlinedFun (pycore_call.h:92)
==518217==    by 0x4A46915: object_vacall (call.c:819)
==518217==    by 0x4A6ABA3: PyObject_CallMethodObjArgs (call.c:879)
==518217==
==518217== 144 bytes in 3 blocks are possibly lost in loss record 209 of 328
==518217==    at 0x484386F: malloc (vg_replace_malloc.c:393)
==518217==    by 0x4A15E02: UnknownInlinedFun (obmalloc.c:101)
==518217==    by 0x4A15E02: UnknownInlinedFun (obmalloc.c:586)
==518217==    by 0x4A15E02: UnknownInlinedFun (obmalloc.c:2003)
==518217==    by 0x4A15E02: UnknownInlinedFun (obmalloc.c:1996)
==518217==    by 0x4A15E02: PyObject_Malloc (obmalloc.c:712)
==518217==    by 0x4A1E109: UnknownInlinedFun (gcmodule.c:2283)
==518217==    by 0x4A1E109: _PyObject_GC_NewVar (gcmodule.c:2318)
==518217==    by 0x4A1FB3A: PyTuple_Pack.constprop.1 (tupleobject.c:166)
==518217==    by 0x4A1AF37: UnknownInlinedFun (typeobject.c:6125)
==518217==    by 0x4A1AF37: UnknownInlinedFun (typeobject.c:6465)
==518217==    by 0x4A1AF37: PyType_Ready (typeobject.c:6513)
==518217==    by 0x4AADF80: UnknownInlinedFun (exceptions.c:3597)
==518217==    by 0x4AADF80: UnknownInlinedFun (pylifecycle.c:734)
==518217==    by 0x4AADF80: pycore_interp_init (pylifecycle.c:845)
==518217==    by 0x4AA96E1: UnknownInlinedFun (pylifecycle.c:901)
==518217==    by 0x4AA96E1: pyinit_core.constprop.0 (pylifecycle.c:1064)
==518217==    by 0x4AA9339: Py_InitializeFromConfig (pylifecycle.c:1254)
==518217==    by 0x4AA8F13: pymain_init (main.c:67)
==518217==    by 0x4AA818F: pymain_main (main.c:701)
==518217==    by 0x4AA7E6A: Py_BytesMain (main.c:734)
==518217==    by 0x4DFA50F: (below main) (libc_start_call_main.h:58)
==518217==
==518217== 168 bytes in 3 blocks are possibly lost in loss record 219 of 328
==518217==    at 0x484386F: malloc (vg_replace_malloc.c:393)
==518217==    by 0x4A15E02: UnknownInlinedFun (obmalloc.c:101)
==518217==    by 0x4A15E02: UnknownInlinedFun (obmalloc.c:586)
==518217==    by 0x4A15E02: UnknownInlinedFun (obmalloc.c:2003)
==518217==    by 0x4A15E02: UnknownInlinedFun (obmalloc.c:1996)
==518217==    by 0x4A15E02: PyObject_Malloc (obmalloc.c:712)
==518217==    by 0x4A1E109: UnknownInlinedFun (gcmodule.c:2283)
==518217==    by 0x4A1E109: _PyObject_GC_NewVar (gcmodule.c:2318)
==518217==    by 0x4A1D636: PyTuple_New (tupleobject.c:75)
==518217==    by 0x4A34416: _PyEval_EvalFrameDefault (ceval.c:3233)
==518217==    by 0x4A2DFC9: UnknownInlinedFun (pycore_ceval.h:73)
==518217==    by 0x4A2DFC9: _PyEval_Vector (ceval.c:6435)
==518217==    by 0x4AB9134: builtin___build_class__ (bltinmodule.c:201)
==518217==    by 0x4A3FE09: cfunction_vectorcall_FASTCALL_KEYWORDS (methodobject.c:443)
==518217==    by 0x4A3FD76: UnknownInlinedFun (pycore_call.h:92)
==518217==    by 0x4A3FD76: PyObject_Vectorcall (call.c:299)
==518217==    by 0x4A321A3: _PyEval_EvalFrameDefault (ceval.c:4772)
==518217==    by 0x4A2DFC9: UnknownInlinedFun (pycore_ceval.h:73)
==518217==    by 0x4A2DFC9: _PyEval_Vector (ceval.c:6435)
==518217==    by 0x4AB7FAB: PyEval_EvalCode (ceval.c:1154)
==518217==
==518217== 192 bytes in 3 blocks are possibly lost in loss record 230 of 328
==518217==    at 0x484386F: malloc (vg_replace_malloc.c:393)
==518217==    by 0x4A15E02: UnknownInlinedFun (obmalloc.c:101)
==518217==    by 0x4A15E02: UnknownInlinedFun (obmalloc.c:586)
==518217==    by 0x4A15E02: UnknownInlinedFun (obmalloc.c:2003)
==518217==    by 0x4A15E02: UnknownInlinedFun (obmalloc.c:1996)
==518217==    by 0x4A15E02: PyObject_Malloc (obmalloc.c:712)
==518217==    by 0x4A1E109: UnknownInlinedFun (gcmodule.c:2283)
==518217==    by 0x4A1E109: _PyObject_GC_NewVar (gcmodule.c:2318)
==518217==    by 0x4A1D636: PyTuple_New (tupleobject.c:75)
==518217==    by 0x4AB4060: mro_implementation (typeobject.c:1946)
==518217==    by 0x4AB3E5C: UnknownInlinedFun (typeobject.c:2083)
==518217==    by 0x4AB3E5C: mro_internal (typeobject.c:2140)
==518217==    by 0x4A19D14: UnknownInlinedFun (typeobject.c:6215)
==518217==    by 0x4A19D14: UnknownInlinedFun (typeobject.c:6468)
==518217==    by 0x4A19D14: PyType_Ready (typeobject.c:6513)
==518217==    by 0x4AADF80: UnknownInlinedFun (exceptions.c:3597)
==518217==    by 0x4AADF80: UnknownInlinedFun (pylifecycle.c:734)
==518217==    by 0x4AADF80: pycore_interp_init (pylifecycle.c:845)
==518217==    by 0x4AA96E1: UnknownInlinedFun (pylifecycle.c:901)
==518217==    by 0x4AA96E1: pyinit_core.constprop.0 (pylifecycle.c:1064)
==518217==    by 0x4AA9339: Py_InitializeFromConfig (pylifecycle.c:1254)
==518217==    by 0x4AA8F13: pymain_init (main.c:67)
==518217==    by 0x4AA818F: pymain_main (main.c:701)
==518217==
==518217== 288 bytes in 6 blocks are possibly lost in loss record 251 of 328
==518217==    at 0x484386F: malloc (vg_replace_malloc.c:393)
==518217==    by 0x4A15E02: UnknownInlinedFun (obmalloc.c:101)
==518217==    by 0x4A15E02: UnknownInlinedFun (obmalloc.c:586)
==518217==    by 0x4A15E02: UnknownInlinedFun (obmalloc.c:2003)
==518217==    by 0x4A15E02: UnknownInlinedFun (obmalloc.c:1996)
==518217==    by 0x4A15E02: PyObject_Malloc (obmalloc.c:712)
==518217==    by 0x4A1E109: UnknownInlinedFun (gcmodule.c:2283)
==518217==    by 0x4A1E109: _PyObject_GC_NewVar (gcmodule.c:2318)
==518217==    by 0x4A1FB3A: PyTuple_Pack.constprop.1 (tupleobject.c:166)
==518217==    by 0x4A1AF37: UnknownInlinedFun (typeobject.c:6125)
==518217==    by 0x4A1AF37: UnknownInlinedFun (typeobject.c:6465)
==518217==    by 0x4A1AF37: PyType_Ready (typeobject.c:6513)
==518217==    by 0x4AC51E5: PyModule_AddType (modsupport.c:706)
==518217==    by 0x1326BC91: UnknownInlinedFun (_datetimemodule.c:6739)
==518217==    by 0x1326BC91: PyInit__datetime (_datetimemodule.c:6916)
==518217==    by 0x4AE60B0: UnknownInlinedFun (importdl.c:169)
==518217==    by 0x4AE60B0: UnknownInlinedFun (import.c:2385)
==518217==    by 0x4AE60B0: _imp_create_dynamic (import.c.h:446)
==518217==    by 0x4A4CA90: cfunction_vectorcall_FASTCALL (methodobject.c:427)
==518217==    by 0x4A3638A: _PyEval_EvalFrameDefault (ceval.c:5379)
==518217==    by 0x4A2DFC9: UnknownInlinedFun (pycore_ceval.h:73)
==518217==    by 0x4A2DFC9: _PyEval_Vector (ceval.c:6435)
==518217==    by 0x4A46915: UnknownInlinedFun (pycore_call.h:92)
==518217==    by 0x4A46915: object_vacall (call.c:819)
==518217==
==518217== 422 bytes in 7 blocks are possibly lost in loss record 267 of 328
==518217==    at 0x484386F: malloc (vg_replace_malloc.c:393)
==518217==    by 0x4A15E02: UnknownInlinedFun (obmalloc.c:101)
==518217==    by 0x4A15E02: UnknownInlinedFun (obmalloc.c:586)
==518217==    by 0x4A15E02: UnknownInlinedFun (obmalloc.c:2003)
==518217==    by 0x4A15E02: UnknownInlinedFun (obmalloc.c:1996)
==518217==    by 0x4A15E02: PyObject_Malloc (obmalloc.c:712)
==518217==    by 0x4A174EB: PyUnicode_New (unicodeobject.c:1425)
==518217==    by 0x4A16794: unicode_decode_utf8 (unicodeobject.c:5117)
==518217==    by 0x13F756B9: string_view_to_python_string (jsoninter.h:21)
==518217==    by 0x13F756B9: __pyx_gb_10cysimdjson_10cysimdjson_10JSONObject_7generator1(__pyx_CoroutineObject*, _ts*, _object*) (cysimdjson.cpp:2326)
==518217==    by 0x13F72910: __Pyx_Coroutine_SendEx(__pyx_CoroutineObject*, _object*, int) [clone .constprop.0] (cysimdjson.cpp:11783)
==518217==    by 0x4A31F31: _PyEval_EvalFrameDefault (ceval.c:4339)
==518217==    by 0x4A2DFC9: UnknownInlinedFun (pycore_ceval.h:73)
==518217==    by 0x4A2DFC9: _PyEval_Vector (ceval.c:6435)
==518217==    by 0x4AB7FAB: PyEval_EvalCode (ceval.c:1154)
==518217==    by 0x4AD7152: run_eval_code_obj (pythonrun.c:1714)
==518217==    by 0x4AD3689: run_mod (pythonrun.c:1735)
==518217==    by 0x4AE96B1: pyrun_file (pythonrun.c:1630)
==518217==
==518217== 422 (184 direct, 238 indirect) bytes in 1 blocks are definitely lost in loss record 268 of 328
==518217==    at 0x484386F: malloc (vg_replace_malloc.c:393)
==518217==    by 0x4A15E02: UnknownInlinedFun (obmalloc.c:101)
==518217==    by 0x4A15E02: UnknownInlinedFun (obmalloc.c:586)
==518217==    by 0x4A15E02: UnknownInlinedFun (obmalloc.c:2003)
==518217==    by 0x4A15E02: UnknownInlinedFun (obmalloc.c:1996)
==518217==    by 0x4A15E02: PyObject_Malloc (obmalloc.c:712)
==518217==    by 0x4A3F76C: UnknownInlinedFun (object.c:189)
==518217==    by 0x4A3F76C: _PyCode_New (codeobject.c:481)
==518217==    by 0x4B1CC0C: PyCode_NewWithPosOnlyArgs (codeobject.c:610)
==518217==    by 0x4B1C50F: UnknownInlinedFun (codeobject.c:1975)
==518217==    by 0x4B1C50F: code_replace (codeobject.c.h:397)
==518217==    by 0x4A3FE09: cfunction_vectorcall_FASTCALL_KEYWORDS (methodobject.c:443)
==518217==    by 0x4A5875A: _PyVectorcall_Call (call.c:257)
==518217==    by 0x13F6F5A1: __Pyx_PyCode_New (cysimdjson.cpp:460)
==518217==    by 0x13F6F5A1: __Pyx_InitCachedConstants (cysimdjson.cpp:8379)
==518217==    by 0x13F6F5A1: __pyx_pymod_exec_cysimdjson(_object*) (cysimdjson.cpp:8755)
==518217==    by 0x4ABE182: PyModule_ExecDef (moduleobject.c:419)
==518217==    by 0x4AC4A5C: UnknownInlinedFun (import.c:2426)
==518217==    by 0x4AC4A5C: _imp_exec_builtin (import.c.h:504)
==518217==    by 0x4A46484: cfunction_vectorcall_O (methodobject.c:514)
==518217==    by 0x4A3638A: _PyEval_EvalFrameDefault (ceval.c:5379)
==518217==
==518217== 624 bytes in 13 blocks are possibly lost in loss record 280 of 328
==518217==    at 0x484386F: malloc (vg_replace_malloc.c:393)
==518217==    by 0x4A15E02: UnknownInlinedFun (obmalloc.c:101)
==518217==    by 0x4A15E02: UnknownInlinedFun (obmalloc.c:586)
==518217==    by 0x4A15E02: UnknownInlinedFun (obmalloc.c:2003)
==518217==    by 0x4A15E02: UnknownInlinedFun (obmalloc.c:1996)
==518217==    by 0x4A15E02: PyObject_Malloc (obmalloc.c:712)
==518217==    by 0x4A1E109: UnknownInlinedFun (gcmodule.c:2283)
==518217==    by 0x4A1E109: _PyObject_GC_NewVar (gcmodule.c:2318)
==518217==    by 0x4A1D636: PyTuple_New (tupleobject.c:75)
==518217==    by 0x4A2F0AB: r_object (marshal.c:1215)
==518217==    by 0x4A2F1EA: r_object (marshal.c:1221)
==518217==    by 0x4A2F3C9: r_object (marshal.c:1394)
==518217==    by 0x4AB87B3: read_object (marshal.c:1521)
==518217==    by 0x4ADDEBE: UnknownInlinedFun (marshal.c:1828)
==518217==    by 0x4ADDEBE: marshal_loads (marshal.c.h:148)
==518217==    by 0x4A46484: cfunction_vectorcall_O (methodobject.c:514)
==518217==    by 0x4A3FD76: UnknownInlinedFun (pycore_call.h:92)
==518217==    by 0x4A3FD76: PyObject_Vectorcall (call.c:299)
==518217==    by 0x4A321A3: _PyEval_EvalFrameDefault (ceval.c:4772)
==518217==
==518217== 1,008 bytes in 21 blocks are possibly lost in loss record 295 of 328
==518217==    at 0x484386F: malloc (vg_replace_malloc.c:393)
==518217==    by 0x4A15E02: UnknownInlinedFun (obmalloc.c:101)
==518217==    by 0x4A15E02: UnknownInlinedFun (obmalloc.c:586)
==518217==    by 0x4A15E02: UnknownInlinedFun (obmalloc.c:2003)
==518217==    by 0x4A15E02: UnknownInlinedFun (obmalloc.c:1996)
==518217==    by 0x4A15E02: PyObject_Malloc (obmalloc.c:712)
==518217==    by 0x4A1E109: UnknownInlinedFun (gcmodule.c:2283)
==518217==    by 0x4A1E109: _PyObject_GC_NewVar (gcmodule.c:2318)
==518217==    by 0x4A1FB3A: PyTuple_Pack.constprop.1 (tupleobject.c:166)
==518217==    by 0x4A1AF37: UnknownInlinedFun (typeobject.c:6125)
==518217==    by 0x4A1AF37: UnknownInlinedFun (typeobject.c:6465)
==518217==    by 0x4A1AF37: PyType_Ready (typeobject.c:6513)
==518217==    by 0x4AC51E5: PyModule_AddType (modsupport.c:706)
==518217==    by 0x4AE46BF: itertoolsmodule_exec (itertoolsmodule.c:4870)
==518217==    by 0x4ABE182: PyModule_ExecDef (moduleobject.c:419)
==518217==    by 0x4AC4A5C: UnknownInlinedFun (import.c:2426)
==518217==    by 0x4AC4A5C: _imp_exec_builtin (import.c.h:504)
==518217==    by 0x4A46484: cfunction_vectorcall_O (methodobject.c:514)
==518217==    by 0x4A3638A: _PyEval_EvalFrameDefault (ceval.c:5379)
==518217==    by 0x4A2DFC9: UnknownInlinedFun (pycore_ceval.h:73)
==518217==    by 0x4A2DFC9: _PyEval_Vector (ceval.c:6435)
==518217==
==518217== 1,064 bytes in 19 blocks are possibly lost in loss record 296 of 328
==518217==    at 0x484386F: malloc (vg_replace_malloc.c:393)
==518217==    by 0x4A15E02: UnknownInlinedFun (obmalloc.c:101)
==518217==    by 0x4A15E02: UnknownInlinedFun (obmalloc.c:586)
==518217==    by 0x4A15E02: UnknownInlinedFun (obmalloc.c:2003)
==518217==    by 0x4A15E02: UnknownInlinedFun (obmalloc.c:1996)
==518217==    by 0x4A15E02: PyObject_Malloc (obmalloc.c:712)
==518217==    by 0x4A1E109: UnknownInlinedFun (gcmodule.c:2283)
==518217==    by 0x4A1E109: _PyObject_GC_NewVar (gcmodule.c:2318)
==518217==    by 0x4A1D636: PyTuple_New (tupleobject.c:75)
==518217==    by 0x4AB4060: mro_implementation (typeobject.c:1946)
==518217==    by 0x4AB3E5C: UnknownInlinedFun (typeobject.c:2083)
==518217==    by 0x4AB3E5C: mro_internal (typeobject.c:2140)
==518217==    by 0x4A19D14: UnknownInlinedFun (typeobject.c:6215)
==518217==    by 0x4A19D14: UnknownInlinedFun (typeobject.c:6468)
==518217==    by 0x4A19D14: PyType_Ready (typeobject.c:6513)
==518217==    by 0x4AC51E5: PyModule_AddType (modsupport.c:706)
==518217==    by 0x4AE46BF: itertoolsmodule_exec (itertoolsmodule.c:4870)
==518217==    by 0x4ABE182: PyModule_ExecDef (moduleobject.c:419)
==518217==    by 0x4AC4A5C: UnknownInlinedFun (import.c:2426)
==518217==    by 0x4AC4A5C: _imp_exec_builtin (import.c.h:504)
==518217==    by 0x4A46484: cfunction_vectorcall_O (methodobject.c:514)
==518217==
==518217== 16,801,200 bytes in 280,020 blocks are definitely lost in loss record 328 of 328
==518217==    at 0x484386F: malloc (vg_replace_malloc.c:393)
==518217==    by 0x4A15E02: UnknownInlinedFun (obmalloc.c:101)
==518217==    by 0x4A15E02: UnknownInlinedFun (obmalloc.c:586)
==518217==    by 0x4A15E02: UnknownInlinedFun (obmalloc.c:2003)
==518217==    by 0x4A15E02: UnknownInlinedFun (obmalloc.c:1996)
==518217==    by 0x4A15E02: PyObject_Malloc (obmalloc.c:712)
==518217==    by 0x4A174EB: PyUnicode_New (unicodeobject.c:1425)
==518217==    by 0x4A16794: unicode_decode_utf8 (unicodeobject.c:5117)
==518217==    by 0x13F756B9: string_view_to_python_string (jsoninter.h:21)
==518217==    by 0x13F756B9: __pyx_gb_10cysimdjson_10cysimdjson_10JSONObject_7generator1(__pyx_CoroutineObject*, _ts*, _object*) (cysimdjson.cpp:2326)
==518217==    by 0x13F72910: __Pyx_Coroutine_SendEx(__pyx_CoroutineObject*, _object*, int) [clone .constprop.0] (cysimdjson.cpp:11783)
==518217==    by 0x4A31F31: _PyEval_EvalFrameDefault (ceval.c:4339)
==518217==    by 0x4A2DFC9: UnknownInlinedFun (pycore_ceval.h:73)
==518217==    by 0x4A2DFC9: _PyEval_Vector (ceval.c:6435)
==518217==    by 0x4AB7FAB: PyEval_EvalCode (ceval.c:1154)
==518217==    by 0x4AD7152: run_eval_code_obj (pythonrun.c:1714)
==518217==    by 0x4AD3689: run_mod (pythonrun.c:1735)
==518217==    by 0x4AE96B1: pyrun_file (pythonrun.c:1630)
==518217==
==518217== LEAK SUMMARY:
==518217==    definitely lost: 16,801,496 bytes in 280,023 blocks
==518217==    indirectly lost: 238 bytes in 4 blocks
==518217==      possibly lost: 6,390 bytes in 119 blocks
==518217==    still reachable: 219,484 bytes in 1,121 blocks
==518217==         suppressed: 0 bytes in 0 blocks
==518217== Reachable blocks (those to which a pointer was found) are not shown.
==518217== To see them, rerun with: --leak-check=full --show-leak-kinds=all
==518217==
==518217== Use --track-origins=yes to see where uninitialised values come from
==518217== For lists of detected and suppressed errors, rerun with: -s
==518217== ERROR SUMMARY: 147 errors from 51 contexts (suppressed: 0 from 0)